Workbook
Name \A: #REF!
Name \B: #REF!
Name \C: #REF!
Name \D: #REF!
Name \E: #REF!
Name \F: #REF!
Name \G: #REF!
Name \H: #REF!
Name \I: #REF!
Name \J: #REF!
Name \K: #REF!
Name \L: #REF!
Name \M: '[1]RT 21'!#REF!
Name \MM: '[1]RT 21'!#REF!
Name \P: '[1]RT 21'!#REF!
Name \PP: '[1]RT 21'!#REF!
Name \S: '[1]RT 21'!#REF!
Name \SS: '[1]RT 21'!#REF!
Name ____________________________JUL11: '[2]FY03-04 Budget'!#REF!
Name ____________________________JUL29: '[2]FY03-04 Budget'!#REF!
Name ____________________________JUL34: '[2]FY03-04 Budget'!#REF!
Name ____________________________JUN30: '[2]FY03-04 Budget'!#REF!
Name ____________________________JUN36: '[2]FY03-04 Budget'!#REF!
Name ____________________________MAY10: '[3]MAY '!$E$10
Name ____________________________MAY11: '[3]MAY '!$E$11
Name ____________________________MAY14: '[3]MAY '!$E$14
Name ____________________________MAY15: '[3]MAY '!$E$15
Name ____________________________MAY16: '[3]MAY '!$E$16
Name ____________________________MAY17: '[3]MAY '!$E$17
Name ____________________________MAY18: '[3]MAY '!$E$18
Name ____________________________MAY19: '[3]MAY '!$E$19
Name ____________________________MAY20: '[3]MAY '!$E$20
Name ____________________________MAY21: '[3]MAY '!$E$21
Name ____________________________MAY22: '[3]MAY '!$E$22
Name ____________________________MAY23: '[3]MAY '!$E$23
Name ____________________________MAY24: '[3]MAY '!$E$24
Name ____________________________MAY25: '[3]MAY '!$E$25
Name ____________________________MAY26: '[3]MAY '!$E$26
Name ____________________________MAY27: '[3]MAY '!$E$27
Name ____________________________MAY28: '[3]MAY '!$E$28
Name ____________________________MAY30: '[3]MAY '!$E$30
Name ____________________________MAY33: '[3]MAY '!$E$33
Name ____________________________MAY34: '[3]MAY '!$E$34
Name ____________________________MAY35: '[3]MAY '!$E$35
Name ____________________________MAY4: '[3]MAY '!$E$4
Name ____________________________MAY5: '[3]MAY '!$E$5
Name ____________________________MAY6: '[3]MAY '!$E$6
Name ____________________________MAY7: '[3]MAY '!$E$7
Name ____________________________MAY8: '[3]MAY '!$E$8
Name ____________________________MAY9: '[3]MAY '!$E$9
Name _____________________JUL11: '[2]FY03-04 Budget'!#REF!
Name _____________________JUL29: '[2]FY03-04 Budget'!#REF!
Name _____________________JUL34: '[2]FY03-04 Budget'!#REF!
Name _____________________JUN30: '[2]FY03-04 Budget'!#REF!
Name _____________________JUN36: '[2]FY03-04 Budget'!#REF!
Name _____________________MAY10: '[3]MAY '!$E$10
Name _____________________MAY11: '[3]MAY '!$E$11
Name _____________________MAY14: '[3]MAY '!$E$14
Name _____________________MAY15: '[3]MAY '!$E$15
Name _____________________MAY16: '[3]MAY '!$E$16

Sheet For Slides
A1: HILL COUNTRY TRANSIT DISTRICT
A2: FY2024 Proposed Budget (1/1/24 - 12/31/24)
A3: Presented to Board of Directors 11/20/23
C6: In Service | D6: In Service
B7: Commuter Bus Allocation Based on Census 2020 Population by City | S7: Commuter Bus Allocation Based on Census 2020 Population by City
C8: Vehicles | D8: Vehicles | F8: Cost Estimate | G8: Population | J8: Hours | T8: Cost Estimate | U8: Population | W8: Allocated Cost | X8: Hours
B9: TEMPLE | C9: 9 | D9: 12 | G9: 82073 | H9: =G9/G14 -> 0.24921128 | I9: =H9*$F$14 -> 209935.58 | J9: =F155 -> 39832 | K9: =J9/J14 -> 0.33765089 | L9: =J9/(J9+J10) -> 0.80293501 | S9: TEMPLE | U9: 82073 | V9: =U9/U14 -> 0.24921128 | W9: =V9*$F$14 -> 209935.58 | X9: =$F$30*V9 -> 2332.6176
B10: BELTON | C10: 2 | D10: 3 | G10: 23054 | H10: =G10/G14 -> 0.07000252 | I10: =H10*$F$14 -> 58970.123 | J10: =F134 -> 9776 | K10: =J10/J14 -> 0.082869931 | L10: =J10/(J9+J10) -> 0.19706499 | S10: BELTON | U10: 23054 | V10: =U10/U14 -> 0.07000252 | W10: =V10*$F$14 -> 58970.123 | X10: =$F$30*V10 -> 655.22359
B11: KILLEEN | C11: 11 | D11: 15 | G11: 153143 | H11: =G11/G14 -> 0.4650124 | I11: =H11*$F$14 -> 391726.45 | J11: =F112 -> 49192 | K11: =J11/J14 -> 0.41699444 | L11: =J11/(J11+J12+J13) -> 0.71960211 | S11: KILLEEN | U11: 153143 | V11: =U11/U14 -> 0.4650124 | W11: =V11*$F$14 -> 391726.45 | X11: =$F$30*V11 -> 4352.5161
B12: COPPERAS COVE | C12: 2 | D12: 3 | G12: 37964 | H12: =G12/G14 -> 0.11527612 | I12: =H12*$F$14 -> 97108.604 | J12: =F70 -> 9600 | K12: =J12/J14 -> 0.081378001 | L12: =J12/(J11+J12+J13) -> 0.140433 | S12: COPPERAS COVE | U12: 37964 | V12: =U12/U14 -> 0.11527612 | W12: =V12*$F$14 -> 97108.604 | X12: =$F$30*V12 -> 1078.9845
B13: HARKER HEIGHTS | C13: 2 | D13: 3 | G13: 33097 | H13: =G13/G14 -> 0.10049768 | I13: =H13*$F$14 -> 84659.242 | J13: =F91 -> 9568 | K13: =J13/J14 -> 0.081106741 | L13: =J13/(J11+J12+J13) -> 0.13996489 | S13: HARKER HEIGHTS | U13: 33097 | V13: =U13/U14 -> 0.10049768 | W13: =V13*$F$14 -> 84659.242 | X13: =$F$30*V13 -> 940.65824
C14: =SUM(C9:C13) -> 26 | D14: =SUM(D9:D13) -> 36 | F14: =12*260*3*90 -> 842400 | G14: =SUM(G9:G13) -> 329331 | H14: =SUM(H9:H13) -> 1 | I14: =SUM(I9:I13) -> 842400 | J14: =SUM(J9:J13) -> 117968 | K14: =SUM(K9:K13) -> 1 | T14: =12*260*3*90 -> 842400 | U14: =SUM(U9:U13) -> 329331 | V14: =SUM(V9:V13) -> 1 | W14: =SUM(W9:W13) -> 842400 | X14: =SUM(X9:X13) -> 9360
B16: Average Fare | C16: 1
B18: FY24 Budget Targets
B19: As of 6/6/2023
B20: Fully Allocated Expenses | C20: Avg. Daily | D20: Avg. Fleet During | F20: Annual Vehicle Revenue Hours | I20: Annual Passengers | L20: Proposed | P20: FY23
B21: Microtransit On-demand All Urban Zones | C21: Service Hours | D21: Service Hours | G21: Contingency | H21: Contingency | L21: FY24 | P21: Budget
B22: All Zones - Avg. Wait Times 30min Peak | C22: 260 Weekdays | F22: Budget | G22: +10% | H22: +20% | I22: Low | J22: Med | K22: High | L22: Budget | M22: +10% | N22: +20% | O22: Diff Lo/Hi
B23: 7am - 11am + 3pm - 7pm | C23: 8 | D23: =D14 -> 36 | F23: =(C23*D23*260) -> 74880 | G23: =F23*1.1 -> 82368 | H23: =F23*1.2 -> 89856 | I23: =F23*5 -> 374400 | J23: =F23*5.5 -> 411840 | K23: =F23*6 -> 449280 | L23: =F23*65 -> 4867200 | M23: =G23*65 -> 5353920 | N23: =H23*65 -> 5840640 | R23: =L63+L84+L105+L127+L148 -> 4867200
B24: All Zones - Avg. Wait Times 40min Off Peak | C24: 260 Weekdays
B25: 11am - 3pm + 7pm - 9pm | C25: 6 | D25: =C14 -> 26 | F25: =(C25*D25*260) -> 40560 | G25: =F25*1.1 -> 44616 | H25: =F25*1.2 -> 48672 | I25: =F25*3 -> 121680 | J25: =F25*4 -> 162240 | K25: =F25*5 -> 202800 | L25: =F25*65 -> 2636400 | M25: =G25*65 -> 2900040 | N25: =H25*65 -> 3163680 | R25: =L65+L86+L107+L129+L150 -> 2636400
B26: All Zones - Avg. Wait Times 30min Off Peak | C26: 52 Weekend Days
B27: TNC Service Provider | L27: =L67+L88+L109+L131+L151 -> 670453 | R27: =L67+L88+L109+L131+L151 -> 670453
B28: Medicaid Trips (50 daily) | C28: 8 | D28: 6 | F28: =F68+F89+F110+F132+F153 -> 2528 | G28: =F28*1.1 -> 2780.8 | H28: =F28*1.2 -> 3033.6 | I28: =F28*1.5 -> 3792 | J28: =G28*1.5 -> 4171.2 | K28: =H28*1.5 -> 4550.4 | L28: =F28*65 -> 164320 | M28: =G28*65 -> 180752 | N28: =H28*65 -> 197184 | R28: =L68+L89+L110+L132+L153 -> 164320
B29: Total Microtransit On-demand | F29: =SUM(F23:F28) -> 117968 | G29: =SUM(G23:G28) -> 129764.8 | H29: =SUM(H23:H28) -> 141561.6 | I29: =SUM(I23:I28) -> 499872 | J29: =SUM(J23:J28) -> 578251.2 | K29: =SUM(K23:K28) -> 656630.4 | L29: =SUM(L23:L28) -> 8338373 | M29: =SUM(M23:M28) -> 8434712 | N29: =SUM(N23:N28) -> 9201504
B30: Commuter Bus - Stops in Temple, Belton, Nolanville, Harker Heights, Killeen, Copperas Cove | C30: 12 | D30: 3 | F30: =(C30*D30*260) -> 9360 | G30: =F30*1.1 -> 10296 | H30: =F30*1.2 -> 11232 | I30: =10*5*2*290 -> 29000 | J30: =10*7*2*290 -> 40600 | K30: =10*8*2*290 -> 46400 | L30: =F30*90 -> 842400 | M30: =12*259*86*6 -> 1603728 | N30: =12*259*86*6 -> 1603728
B31: Rural | D31: 20 | F31: 32958.05 | J31: 70000 | L31: 2641604 | M31: 2592992 | N31: 2592992
B32: Fort Cavazos (No Fare) | F32: 56548 | J32: 169644 | L32: =4241400-(F32*10) -> 3675920 | S32: County | T32: State & Fed Funding Allocation | U32: NEMT Revenue | V32: Local Funding Contributions | W32: FY24 Budget Target | X32: FY24 County Funding Commitment
B33: Total Projected Expense | F33: =F29+F30+F31+F32 -> 216834.05 | G33: =G29+G30+G31+G32 -> 140060.8 | H33: =H29+H30+H31+H32 -> 152793.6 | I33: =I29+I30+I31+I32 -> 528872 | J33: =J29+J30+J31+J32 -> 858495.2 | K33: =K29+K30+K31+K32 -> 703030.4 | L33: =L29+L30+L31+L32 -> 15498297 | M33: =SUM(M29:M31) -> 12631432 | N33: =SUM(N29:N31) -> 13398224 | O33: =N33-L33 -> -2100073 | P33: =5149835+2883500+3001770 -> 11035105
B34: Projected Revenue
B35: Federal Grant Revenue | L35: =(L48+L51+L54)*-1 -> -6164398 | M35: =-(2970479+1673250+1253517) -> -5897246 | N35: =-(2970479+1673250+1253517) -> -5897246 | P35: =-(2970479+1673250+1253517) -> -5897246 | S35: Bell County | T35: 60476.325 | U35: 9383 | V35: 134383 | W35: 100793 | X35: 125000 | Z35: =ROUND(W35,0) -> 100793
B36: Federal Grant Carbon Reduction Grant | L36: -500000 | S36: Coryell County | T36: 197197.34 | U36: 30595 | V36: 104111 | W36: 301309 | X36: 50000 | Z36: =ROUND(W36,0) -> 301309
B37: State Revenue | L37: =(L49+L52+L55)*-1 -> -1525568 | M37: =-(415133+519759+601585) -> -1536477 | N37: =-(415133+519759+601585) -> -1536477 | P37: =-(415133+519759+601585) -> -1536477 | S37: Hamilton County | T37: 174565.1 | U37: 0 | V37: 0 | W37: 174565 | X37: 0 | Z37: =ROUND(W37,0) -> 174565
B38: Urban Medicaid Revenue | L38: -1113000 | M38: -1400000 | N38: -1400000 | P38: =-917223-634691-404368 -> -1956282 | S38: Lampasas County | T38: 179759.38 | U38: 27890 | V38: 119839 | W38: 299598 | X38: 68433 | Z38: =ROUND(W38,0) -> 299598
B39: Fare Revenue | L39: =((J29+J30+J31)*C16)*-1 -> -688851.2 | S39: Llano County | T39: 303680.2 | U39: 47116 | V39: 202451 | W39: 506131 | X39: 155335 | Z39: =ROUND(W39,0) -> 506131
B40: Killeen Local | L40: =L117*-1 -> -650000 | S40: Mason County | T40: 88117.345 | U40: 13671 | V40: 58744 | W40: 146862 | X40: 45073 | Z40: =ROUND(W40,0) -> 146862
B41: Temple Local | L41: =L162*-1 -> -308936.66 | S41: Milam County | T41: 601053.05 | U41: 93254 | V41: 215287 | W41: 816341 | X41: 75000 | Z41: =ROUND(W41,0) -> 816341
B42: Belton Local | L42: =L141*-1 -> -55372.768 | S42: Mills County | T42: 116500.41 | U42: 0 | V42: 0 | W42: 116500 | X42: 0 | Z42: =ROUND(W42,0) -> 116500
B43: Copperas Cove Local | L43: =L77*-1 -> -94462.808 | S43: San Saba | T43: 133752.85 | U43: 20752 | V43: 45752 | W43: 179505 | X43: 25000 | Z43: =ROUND(W43,0) -> 179505
B44: Harker Heights Local | L44: =L98*-1 -> -64999.85 | T44: =SUM(T35:T43) -> 1855102 | U44: =SUM(U35:U43) -> 242661 | V44: =SUM(V35:V43) -> 880567 | W44: =SUM(W35:W43) -> 2641604 | X44: =SUM(X35:X43) -> 543841 | Z44: =SUM(Z35:Z43) -> 2641604
...

Sheet Financial Plan OUTPUTS>>>

Sheet T1 Summary Table
E7: TABLE 1: Tahoe Basin Operating Financial Forecast Summary With Recommended Plan Elements
F9: FY 26-27(2027) | G9: FY 27-28 (2028) | H9: FY 28-29 (2029) | I9: FY 29-30 (2030) | J9: FY 30-31 (2031) | L9: 2027 %s
E11: Estimated Total Operating Cost (Status Quo) | F11: =SUM('T2-4 A1 TTD LL Costs'!G220,'T2-4 A1 TTD LL Costs'!G243,'T5-7 TART TNTTMA FinancialPlan'!G129,'T5-7 TART TNTTMA FinancialPlan'!G175) -> 23108271 | G11: =SUM('T2-4 A1 TTD LL Costs'!H220,'T2-4 A1 TTD LL Costs'!H243,'T5-7 TART TNTTMA FinancialPlan'!H129,'T5-7 TART TNTTMA FinancialPlan'!H175) -> 24018006 | H11: =SUM('T2-4 A1 TTD LL Costs'!I220,'T2-4 A1 TTD LL Costs'!I243,'T5-7 TART TNTTMA FinancialPlan'!I129,'T5-7 TART TNTTMA FinancialPlan'!I175) -> 24434407 | I11: =SUM('T2-4 A1 TTD LL Costs'!J220,'T2-4 A1 TTD LL Costs'!J243,'T5-7 TART TNTTMA FinancialPlan'!J129,'T5-7 TART TNTTMA FinancialPlan'!J175) -> 25544180 | J11: =SUM('T2-4 A1 TTD LL Costs'!K220,'T2-4 A1 TTD LL Costs'!K243,'T5-7 TART TNTTMA FinancialPlan'!K129,'T5-7 TART TNTTMA FinancialPlan'!K175) -> 26541674
E12: Estimated Total Operating Cost (w/ Service Plan) | F12: =SUM('T2-4 A1 TTD LL Costs'!G221,'T2-4 A1 TTD LL Costs'!G244,'T5-7 TART TNTTMA FinancialPlan'!G130,'T5-7 TART TNTTMA FinancialPlan'!G176) -> 23599171 | G12: =SUM('T2-4 A1 TTD LL Costs'!H221,'T2-4 A1 TTD LL Costs'!H244,'T5-7 TART TNTTMA FinancialPlan'!H130,'T5-7 TART TNTTMA FinancialPlan'!H176) -> 26067506 | H12: =SUM('T2-4 A1 TTD LL Costs'!I221,'T2-4 A1 TTD LL Costs'!I244,'T5-7 TART TNTTMA FinancialPlan'!I130,'T5-7 TART TNTTMA FinancialPlan'!I176) -> 27095907 | I12: =SUM('T2-4 A1 TTD LL Costs'!J221,'T2-4 A1 TTD LL Costs'!J244,'T5-7 TART TNTTMA FinancialPlan'!J130,'T5-7 TART TNTTMA FinancialPlan'!J176) -> 28307580 | J12: =SUM('T2-4 A1 TTD LL Costs'!K221,'T2-4 A1 TTD LL Costs'!K244,'T5-7 TART TNTTMA FinancialPlan'!K130,'T5-7 TART TNTTMA FinancialPlan'!K176) -> 29636474
E14: Total Revenue | F14: =SUM('T2-4 A1 TTD LL Costs'!G223,'T2-4 A1 TTD LL Costs'!G246,'T5-7 TART TNTTMA FinancialPlan'!G132,'T5-7 TART TNTTMA FinancialPlan'!G178) -> 27076406 | G14: =SUM('T2-4 A1 TTD LL Costs'!H223,'T2-4 A1 TTD LL Costs'!H246,'T5-7 TART TNTTMA FinancialPlan'!H132,'T5-7 TART TNTTMA FinancialPlan'!H178) -> 24601799 | H14: =SUM('T2-4 A1 TTD LL Costs'!I223,'T2-4 A1 TTD LL Costs'!I246,'T5-7 TART TNTTMA FinancialPlan'!I132,'T5-7 TART TNTTMA FinancialPlan'!I178) -> 24468850 | I14: =SUM('T2-4 A1 TTD LL Costs'!J223,'T2-4 A1 TTD LL Costs'!J246,'T5-7 TART TNTTMA FinancialPlan'!J132,'T5-7 TART TNTTMA FinancialPlan'!J178) -> 24646600 | J14: =SUM('T2-4 A1 TTD LL Costs'!K223,'T2-4 A1 TTD LL Costs'!K246,'T5-7 TART TNTTMA FinancialPlan'!K132,'T5-7 TART TNTTMA FinancialPlan'!K178) -> 25211000
E15: Core Recurring Transit Operating Revenue (FTA, TDA) | F15: =SUM('T2-4 A1 TTD LL Costs'!G224,'T2-4 A1 TTD LL Costs'!G247,'T5-7 TART TNTTMA FinancialPlan'!G133,'T5-7 TART TNTTMA FinancialPlan'!G179) -> 13243732 | G15: =SUM('T2-4 A1 TTD LL Costs'!H224,'T2-4 A1 TTD LL Costs'!H247,'T5-7 TART TNTTMA FinancialPlan'!H133,'T5-7 TART TNTTMA FinancialPlan'!H179) -> 12413500 | H15: =SUM('T2-4 A1 TTD LL Costs'!I224,'T2-4 A1 TTD LL Costs'!I247,'T5-7 TART TNTTMA FinancialPlan'!I133,'T5-7 TART TNTTMA FinancialPlan'!I179) -> 12408500 | I15: =SUM('T2-4 A1 TTD LL Costs'!J224,'T2-4 A1 TTD LL Costs'!J247,'T5-7 TART TNTTMA FinancialPlan'!J133,'T5-7 TART TNTTMA FinancialPlan'!J179) -> 12558400 | J15: =SUM('T2-4 A1 TTD LL Costs'!K224,'T2-4 A1 TTD LL Costs'!K247,'T5-7 TART TNTTMA FinancialPlan'!K133,'T5-7 TART TNTTMA FinancialPlan'!K179) -> 12552400 | L15: =F15/$F$14 -> 0.48912444 | M15: =G15/$F$14 -> 0.45846188 | N15: =H15/$F$14 -> 0.45827722 | O15: =I15/$F$14 -> 0.4638134 | P15: =J15/$F$14 -> 0.46359181
E16: Other State/Federal Funds (LCTOP, CRP) | F16: =SUM('T2-4 A1 TTD LL Costs'!G225,'T2-4 A1 TTD LL Costs'!G248,'T5-7 TART TNTTMA FinancialPlan'!G134,'T5-7 TART TNTTMA FinancialPlan'!G180) -> 545416 | G16: =SUM('T2-4 A1 TTD LL Costs'!H225,'T2-4 A1 TTD LL Costs'!H248,'T5-7 TART TNTTMA FinancialPlan'!H134,'T5-7 TART TNTTMA FinancialPlan'!H180) -> 545090 | H16: =SUM('T2-4 A1 TTD LL Costs'!I225,'T2-4 A1 TTD LL Costs'!I248,'T5-7 TART TNTTMA FinancialPlan'!I134,'T5-7 TART TNTTMA FinancialPlan'!I180) -> 273500 | I16: =SUM('T2-4 A1 TTD LL Costs'!J225,'T2-4 A1 TTD LL Costs'!J248,'T5-7 TART TNTTMA FinancialPlan'!J134,'T5-7 TART TNTTMA FinancialPlan'!J180) -> 8000 | J16: =SUM('T2-4 A1 TTD LL Costs'!K225,'T2-4 A1 TTD LL Costs'!K248,'T5-7 TART TNTTMA FinancialPlan'!K134,'T5-7 TART TNTTMA FinancialPlan'!K180) -> 273500 | L16: =F16/$F$14 -> 0.020143589 | M16: =G16/$F$14 -> 0.020131549 | N16: =H16/$F$14 -> 0.010101045 | O16: =I16/$F$14 -> 0.00029546019 | P16: =J16/$F$14 -> 0.010101045
E17: Public Local Funds (County, City, TOT, etc.) | F17: =SUM('T2-4 A1 TTD LL Costs'!G226,'T2-4 A1 TTD LL Costs'!G249,'T5-7 TART TNTTMA FinancialPlan'!G135,'T5-7 TART TNTTMA FinancialPlan'!G181) -> 9808072 | G17: =SUM('T2-4 A1 TTD LL Costs'!H226,'T2-4 A1 TTD LL Costs'!H249,'T5-7 TART TNTTMA FinancialPlan'!H135,'T5-7 TART TNTTMA FinancialPlan'!H181) -> 9969831 | H17: =SUM('T2-4 A1 TTD LL Costs'!I226,'T2-4 A1 TTD LL Costs'!I249,'T5-7 TART TNTTMA FinancialPlan'!I135,'T5-7 TART TNTTMA FinancialPlan'!I181) -> 10122150 | I17: =SUM('T2-4 A1 TTD LL Costs'!J226,'T2-4 A1 TTD LL Costs'!J249,'T5-7 TART TNTTMA FinancialPlan'!J135,'T5-7 TART TNTTMA FinancialPlan'!J181) -> 10415500 | J17: =SUM('T2-4 A1 TTD LL Costs'!K226,'T2-4 A1 TTD LL Costs'!K249,'T5-7 TART TNTTMA FinancialPlan'!K135,'T5-7 TART TNTTMA FinancialPlan'!K181) -> 10720400 | L17: =F17/$F$14 -> 0.36223685 | M17: =G17/$F$14 -> 0.36821102 | N17: =H17/$F$14 -> 0.37383654 | O17: =I17/$F$14 -> 0.3846707 | P17: =J17/$F$14 -> 0.39593142
E18: SB 125 | F18: =SUM('T2-4 A1 TTD LL Costs'!G227,'T2-4 A1 TTD LL Costs'!G250,'T5-7 TART TNTTMA FinancialPlan'!G136,'T5-7 TART TNTTMA FinancialPlan'!G182) -> 1575000 | G18: =SUM('T2-4 A1 TTD LL Costs'!H227,'T2-4 A1 TTD LL Costs'!H250,'T5-7 TART TNTTMA FinancialPlan'!H136,'T5-7 TART TNTTMA FinancialPlan'!H182) -> 0 | H18: =SUM('T2-4 A1 TTD LL Costs'!I227,'T2-4 A1 TTD LL Costs'!I250,'T5-7 TART TNTTMA FinancialPlan'!I136,'T5-7 TART TNTTMA FinancialPlan'!I182) -> 0 | I18: =SUM('T2-4 A1 TTD LL Costs'!J227,'T2-4 A1 TTD LL Costs'!J250,'T5-7 TART TNTTMA FinancialPlan'!J136,'T5-7 TART TNTTMA FinancialPlan'!J182) -> 0 | J18: =SUM('T2-4 A1 TTD LL Costs'!K227,'T2-4 A1 TTD LL Costs'!K250,'T5-7 TART TNTTMA FinancialPlan'!K136,'T5-7 TART TNTTMA FinancialPlan'!K182) -> 0 | L18: =F18/$F$14 -> 0.058168724 | M18: =G18/$F$14 -> 0 | N18: =H18/$F$14 -> 0 | O18: =I18/$F$14 -> 0 | P18: =J18/$F$14 -> 0
E19: Private/Non Profit Funds | F19: =SUM('T2-4 A1 TTD LL Costs'!G228,'T2-4 A1 TTD LL Costs'!G229,'T2-4 A1 TTD LL Costs'!G251,'T5-7 TART TNTTMA FinancialPlan'!G137,'T5-7 TART TNTTMA FinancialPlan'!G183) -> 882905 | G19: =SUM('T2-4 A1 TTD LL Costs'!H228,'T2-4 A1 TTD LL Costs'!H229,'T2-4 A1 TTD LL Costs'!H251,'T5-7 TART TNTTMA FinancialPlan'!H137,'T5-7 TART TNTTMA FinancialPlan'!H183) -> 945578 | H19: =SUM('T2-4 A1 TTD LL Costs'!I228,'T2-4 A1 TTD LL Costs'!I229,'T2-4 A1 TTD LL Costs'!I251,'T5-7 TART TNTTMA FinancialPlan'!I137,'T5-7 TART TNTTMA FinancialPlan'!I183) -> 936900 | I19: =SUM('T2-4 A1 TTD LL Costs'!J228,'T2-4 A1 TTD LL Costs'!J229,'T2-4 A1 TTD LL Costs'!J251,'T5-7 TART TNTTMA FinancialPlan'!J137,'T5-7 TART TNTTMA FinancialPlan'!J183) -> 936900 | J19: =SUM('T2-4 A1 TTD LL Costs'!K228,'T2-4 A1 TTD LL Costs'!K229,'T2-4 A1 TTD LL Costs'!K251,'T5-7 TART TNTTMA FinancialPlan'!K137,'T5-7 TART TNTTMA FinancialPlan'!K183) -> 936900 | L19: =F19/$F$14 -> 0.03260791 | M19: =G19/$F$14 -> 0.034922582 | N19: =H19/$F$14 -> 0.034602081 | O19: =I19/$F$14 -> 0.034602081 | P19: =J19/$F$14 -> 0.034602081
E20: Fares | F20: =SUM('T2-4 A1 TTD LL Costs'!G252,'T5-7 TART TNTTMA FinancialPlan'!G138,'T5-7 TART TNTTMA FinancialPlan'!G184) -> 449156 | G20: =SUM('T2-4 A1 TTD LL Costs'!H252,'T5-7 TART TNTTMA FinancialPlan'!H138,'T5-7 TART TNTTMA FinancialPlan'!H184) -> 395700 | H20: =SUM('T2-4 A1 TTD LL Costs'!I252,'T5-7 TART TNTTMA FinancialPlan'!I138,'T5-7 TART TNTTMA FinancialPlan'!I184) -> 395700 | I20: =SUM('T2-4 A1 TTD LL Costs'!J252,'T5-7 TART TNTTMA FinancialPlan'!J138,'T5-7 TART TNTTMA FinancialPlan'!J184) -> 395700 | J20: =SUM('T2-4 A1 TTD LL Costs'!K252,'T5-7 TART TNTTMA FinancialPlan'!K138,'T5-7 TART TNTTMA FinancialPlan'!K184) -> 395700 | L20: =F20/$F$14 -> 0.016588465 | M20: =G20/$F$14 -> 0.0146142 | N20: =H20/$F$14 -> 0.0146142 | O20: =I20/$F$14 -> 0.0146142 | P20: =J20/$F$14 -> 0.0146142
E21: Other (Membership, Program Management) | F21: =SUM('T5-7 TART TNTTMA FinancialPlan'!G185) -> 325359 | G21: =SUM('T5-7 TART TNTTMA FinancialPlan'!H185) -> 325400 | H21: =SUM('T5-7 TART TNTTMA FinancialPlan'!I185) -> 325400 | I21: =SUM('T5-7 TART TNTTMA FinancialPlan'!J185) -> 325400 | J21: =SUM('T5-7 TART TNTTMA FinancialPlan'!K185) -> 325400 | L21: =F21/$F$14 -> 0.012016329 | M21: =G21/$F$14 -> 0.012017843 | N21: =H21/$F$14 -> 0.012017843 | O21: =I21/$F$14 -> 0.012017843 | P21: =J21/$F$14 -> 0.012017843
E23: Surplus/Deficit (Status Quo) | F23: =F14-F11 -> 3968135.5 | G23: =G14-G11 -> 583793.2 | H23: =H14-H11 -> 34443.325 | I23: =I14-I11 -> -897579.57 | J23: =J14-J11 -> -1330674
E24: Surplus/Deficit (w/ Service Plan) | F24: =F14-F12 -> 3477235.5 | G24: =G14-G12 -> -1465706.8 | H24: =H14-H12 -> -2627056.7 | I24: =I14-I12 -> -3660979.6 | J24: =J14-J12 -> -4425474 | L24: =SUM(L16,L18,L19,L20,L21) -> 0.13952502 | M24: =SUM(M16,M18,M19,M20,M21) -> 0.081686174
E30: Inflation assumptions in footnote in text
E31: What are notes attached to?
M32: Drop in 5307 funds from no more carryover in 27-28
F41: 1 | G41: TDA
F42: =F41/0.4 -> 2.5 | G42: 5311
G45: 1=.4*X

Sheet Questions
D4: Question | E4: Lake Link | F4: What revenues can we count on for 27-28 for Lake Link?
E6: Kira | F6: Do we recommend Transportation user fee?

Sheet T2-4 A1 TTD LL Costs
G1: FY 26-27 | H1: FY 27-28 | I1: FY 28-29 | J1: FY 29-30 | K1: FY 30-31 | O1: 1.04 | P1: Inflation escalator (general)
A2: TTD | B2: 24-25 VSH | E2: Cost per hr | G2: ='VRH Rates'!D7 -> 123.17 | H2: =G2*$O$1 -> 128.0968 | I2: =H2*$O$1 -> 133.22067 | J2: =I2*$O$1 -> 138.5495 | K2: =J2*$O$1 -> 144.09148 | O2: 1.01 | P2: Growth of FTA funds
B3: ='Operating Stats'!F43 -> 35679.5 | E3: Cost per mi | G3: ='VRH Rates'!E7 -> 1.6 | H3: =G3*$O$1 -> 1.664 | I3: =H3*$O$1 -> 1.73056 | J3: =I3*1.1 -> 1.903616 | K3: =J3*1.03 -> 1.9607245
B5: 24-25 VSM
B6: ='Operating Stats'!G43 -> 534843
A7: Lake Link | B7: 25-26 VSH | E7: Cost per hr | G7: ='VRH Rates'!D9 -> 65.23 | H7: =G7*$O$1 -> 67.8392 | I7: =H7*$O$1 -> 70.552768 | J7: =I7*$O$1 -> 73.374879 | K7: =J7*$O$1 -> 76.309874
B8: ='Operating Stats'!F44 -> 47002 | E8: Cost per mi | G8: 0 | H8: =G8*$O$1 -> 0 | I8: =H8*$O$1 -> 0 | J8: =I8*1.1 -> 0 | K8: =J8*1.03 -> 0
B9: 25-26 VSM
B10: ='Operating Stats'!G15 -> 366322 | E10: Population Change Rate | G10: 0.00025 | H10: 0.00025 | I10: 0.00025 | J10: 0.00025 | K10: 0.00025 | M10: RTP pop projections
D13: TABLE 2: South Shore Operating Costs
G15: FY 26-27 | H15: FY 27-28 | I15: FY 28-29 | J15: FY 29-30 | K15: FY 30-31
D17: TTD Base Case Operating Cost 1
E18: Marginal Operating Costs | G18: =($B$3*G2)+($B$6*G3) -> 5250392.8 | H18: =($B$3*H2)+($B$6*H3) -> 5460408.5 | I18: =($B$3*I2)+($B$6*I3) -> 5678824.9 | J18: =($B$3*J2)+($B$6*J3) -> 5961512.5 | K18: =($B$3*K2)+($B$6*K3) -> 6189791.7
E19: Fixed Costs | G19: ='VRH Rates'!F7 -> 2077415.2 | H19: =G19*$O$1 -> 2160511.8 | I19: =H19*$O$1 -> 2246932.2 | J19: =I19*$O$1 -> 2336809.5 | K19: =J19*$O$1 -> 2430281.9
E20: Emerald Bay Shuttle (Route 30)3 | G20: 517288 | H20: 523384 | I20: 0 | J20: 0 | K20: 0 | M20: =H20/G20-1 -> 0.011784538
E21: Total | G21: =SUM(G18:G20) -> 7845096 | H21: =SUM(H18:H20) -> 8144304.3 | I21: =SUM(I18:I19) -> 7925757.1 | J21: =SUM(J18:J19) -> 8298322.1 | K21: =SUM(K18:K19) -> 8620073.6
D23: Lake Link Base Case Operating Cost 2
E24: Marginal Operating Costs | G24: =($B$8*G7)+($B$10*G8) -> 3065940.5 | H24: =($B$8*H7)+($B$10*H8) -> 3188578.1 | I24: =($B$8*I7)+($B$10*I8) -> 3316121.2 | J24: =($B$8*J7)+($B$10*J8) -> 3448766 | K24: =($B$8*K7)+($B$10*K8) -> 3586716.7
E25: Fixed Costs | G25: ='VRH Rates'!F9+'VRH Rates'!G9+'VRH Rates'!H9 -> 162900 | H25: =G25*$O$1 -> 169416 | I25: =H25*$O$1 -> 176192.64 | J25: =I25*$O$1 -> 183240.35 | K25: =J25*$O$1 -> 190569.96 | Q25: Inflation | R25: 0 | S25: 1.04 | T25: 1.08 | U25: 1.12 | V25: 1.16
E26: Total | G26: =SUM(G24:G25) -> 3228840.5 | H26: =SUM(H24:H25) -> 3357994.1 | I26: =SUM(I24:I25) -> 3492313.8 | J26: =SUM(J24:J25) -> 3632006.4 | K26: =SUM(K24:K25) -> 3777286.7 | Q26: Implementation Plan - Do not Delete
D28: Service Plan Element Marginal Operating Costs | M28: =G21+G26 -> 11073936 | R28: FY 26-27 | S28: FY 27-28 | T28: FY 28-29 | U28: FY 29-30 | V28: FY 30-31
E29: =Q29 -> Eliminate 19X and Replace with US 50 Service (4 Round Trips) | G29: =IF(R29=1,ROUND('[31] T25 Service Alts'!$M$26,-2),0) -> 476500 | H29: =IF(S29=1,ROUND('[31] T25 Service Alts'!$M$26*S25,-2),0) -> 495600 | I29: =IF(T29=1,ROUND('[31] T25 Service Alts'!$M$26*T25,-2),0) -> 514600 | J29: =IF(U29=1,ROUND('[31] T25 Service Alts'!$M$26*U25,-2),0) -> 533700 | K29: =IF(V29=1,ROUND('[31] T25 Service Alts'!$M$26*V25,-2),0) -> 552700 | Q29: Eliminate 19X and Replace with US 50 Service (4 Round Trips) | R29: 1 | S29: 1 | T29: 1 | U29: 1 | V29: 1
E30: =Q30 -> Seasonal Expansion of Route 28 to Spooner Mobility Hub | G30: =IF(R30=1,ROUND('[31] T25 Service Alts'!$M$32,-2),0) -> 0 | H30: =IF(S30=1,ROUND('[31] T25 Service Alts'!$M$30*S25,-2),0) -> 137200 | I30: =IF(T30=1,ROUND('[31] T25 Service Alts'!$M$30*T25,-2),0) -> 142400 | J30: =IF(U30=1,ROUND('[31] T25 Service Alts'!$M$30*U25,-2),0) -> 147700 | K30: =IF(V30=1,ROUND('[31] T25 Service Alts'!$M$30*V25,-2),0) -> 153000 | Q30: Seasonal Expansion of Route 28 to Spooner Mobility Hub | R30: 0 | S30: 1 | T30: 1 | U30: 1 | V30: 1
E31: =Q31 -> Continue to Operate the Emerald Bay Shuttle (Route 30) Beyond the Pilot Period | G31: =IF(R31=1,ROUND('[31] T25 Service Alts'!$M$37,-2),0) -> 0 | H31: =IF(S31=1,ROUND('[31] T25 Service Alts'!$M$37*S25,-2),0) -> 0 | I31: =IF(T31=1,ROUND('[31] T25 Service Alts'!$M$35*T25,-2),0) -> 558700 | J31: =IF(U31=1,ROUND('[31] T25 Service Alts'!$M$35*U25,-2),0) -> 579400 | K31: =IF(V31=1,ROUND('[31] T25 Service Alts'!$M$35*V25,-2),0) -> 600100 | Q31: Continue to Operate the Emerald Bay Shuttle (Route 30) Beyond the Pilot Period | R31: 0 | S31: 0 | T31: 1 | U31: 1 | V31: 1
E32: Pilot Co-mingled Paratransit/Microtransit Service to Meyers 4 | G32: =IF(R32=1,ROUND('[31] T25 Service Alts'!$M$43,-2),0) -> 0 | H32: =IF(S32=1,ROUND('[31] T25 Service Alts'!$M$41*S25,-2),0) -> 357300 | I32: =IF(T32=1,ROUND('[31] T25 Service Alts'!$M$41*T25,-2),0) -> 371000 | J32: =IF(U32=1,ROUND('[31] T25 Service Alts'!$M$41*U25,-2),0) -> 384800 | K32: =IF(V32=1,ROUND('[31] T25 Service Alts'!$M$41*V25,-2),0) -> 398500 | Q32: Pilot Co-mingled Paratransit/Microtransit Service to Meyers | R32: 0 | S32: 1 | T32: 1 | U32: 1 | V32: 1
E33: =Q33 -> Discontinue Route 50 Deviation to LTCC during Summer | G33: =IF(R33=1,ROUND('[31] T25 Service Alts'!$M$37,-2),0) -> -10600 | H33: =IF(S33=1,ROUND('[31] T25 Service Alts'!$M$37*S25,-2),0) -> -11000 | I33: =IF(T33=1,ROUND('[31] T25 Service Alts'!$M$37*T25,-2),0) -> -11400 | J33: =IF(U33=1,ROUND('[31] T25 Service Alts'!$M$37*U25,-2),0) -> -11800 | K33: =IF(V33=1,ROUND('[31] T25 Service Alts'!$M$37*V25,-2),0) -> -12300 | Q33: Discontinue Route 50 Deviation to LTCC during Summer | R33: 1 | S33: 1 | T33: 1 | U33: 1 | V33: 1
E35: TTD Service Plan Costs | G35: =SUM(G29:G31,G33) -> 465900 | H35: =SUM(H29:H31,H33) -> 621800 | I35: =SUM(I29:I31,I33) -> 1204300 | J35: =SUM(J29:J31,J33) -> 1249000 | K35: =SUM(K29:K31,K33) -> 1293500 | M35: =SUM(G35:K35) -> 4834500
E36: Lake Link Service Plan Costs | G36: =SUM(G32) -> 0 | H36: =SUM(H32) -> 357300 | I36: =SUM(I32) -> 371000 | J36: =SUM(J32) -> 384800 | K36: =SUM(K32) -> 398500 | M36: =SUM(G36:K36) -> 1511600
E37: Total Service Plan Costs | G37: =SUM(G29:G34) -> 465900 | H37: =SUM(H29:H34) -> 979100 | I37: =SUM(I29:I34) -> 1575300 | J37: =SUM(J29:J34) -> 1633800 | K37: =SUM(K29:K34) -> 1692000 | M37: =SUM(G37:K37) -> 6346100
D39: Total South Shore Transit Operating Cost (Status Quo) | G39: =G21+G26 -> 11073936 | H39: =H21+H26 -> 11502298 | I39: =I21+I26 -> 11418071 | J39: =J21+J26 -> 11930328 | K39: =K21+K26 -> 12397360
D40: Total South Shore Transit Operating Cost (with Service Plan Elements) | G40: =G21+G26+G35 -> 11539836 | H40: =H21+H26+H35 -> 12124098 | I40: =I21+I26+I35 -> 12622371 | J40: =J21+J26+J35 -> 13179328 | K40: =K21+K26+K35 -> 13690860
D42: Note 1: TTD base case costs based upon FY 2024-25 actual expenses and the LSC Cost Model (Existing Conditions Memo) plus 4% annual inflation and FY 2024-25 service levels. Assumes 4% annual inflation rate moving forward.
D43: Note 2: Lake Link base case costs based upon the current approved SSTMA/Downtowner contract and 2027 projected service levels. Assumes 4% annual inflation rate moving forward.
D44: Note 3: Base Case operating costs reflect 2026 and 2027 operating seasons and correspond with OWP FYs and contract costs.
D45: Note 4: Uses Lake Link costs to project future costs, assuming that this co-mingled service would be operated by a third-party contractor.
D46: Source: LSC Transportation Consultants, Inc.
D55: TABLE A1: South Shore Financial Plan - Operating | M55: 5-Year Plan Revenues/ Costs
B56: APPENDIX
G57: FY 26-27 | H57: FY 27-28 | I57: FY 28-29 | J57: FY 29-30 | K57: FY 30-31 | O57: Notes
D59: OPERATING REVENUE - RECCURING FUNDS
...

Sheet T5-7 TART TNTTMA FinancialPlan
F1: FY 25-26 | G1: FY 26-27 | H1: FY 27-28 | I1: FY 28-29 | J1: FY 29-30 | K1: FY 30-31 | O1: 1.04 | P1: Inflation escalator (general) | Q1: 1 | R1: 1.03 | S1: =R1*$O$1 -> 1.0712 | T1: =S1*$O$1 -> 1.114048 | U1: =T1*$O$1 -> 1.1586099 | V1: =U1*$O$1 -> 1.2049543
A2: TART | B2: 25-26 VSH | E2: Cost per hr | G2: ='VRH Rates'!D14 -> 66.45 | H2: =G2*$O$1 -> 69.108 | I2: =H2*$O$1 -> 71.87232 | J2: =I2*$O$1 -> 74.747213 | K2: =J2*$O$1 -> 77.737101
B3: 35129 | E3: Cost per mi | G3: ='VRH Rates'!E14 -> 1.7 | H3: =G3*$O$1 -> 1.768 | I3: =H3*$O$1 -> 1.83872 | J3: =I3*1.1 -> 2.022592 | K3: =J3*1.03 -> 2.0832698
B5: 25-26 VSM
B6: 696698
A7: TART | B7: 25-26 VSH | E7: Cost per hr | G7: ='VRH Rates'!D15 -> 46.56 | H7: =G7*$O$1 -> 48.4224 | I7: =H7*$O$1 -> 50.359296 | J7: =I7*$O$1 -> 52.373668 | K7: =J7*$O$1 -> 54.468615
A8: Connect | B8: 27343 | E8: Cost per mi | G8: 0 | H8: =G8*$O$1 -> 0 | I8: =H8*$O$1 -> 0 | J8: =I8*1.1 -> 0 | K8: =J8*1.03 -> 0
B10: 25-26 VSM | E10: Base ridership growth (from 25-26 Status Quo) | G10: 1.02 | H10: =+G10*1.02 -> 1.0404 | I10: =+H10*1.02 -> 1.061208 | J10: =+I10*1.02 -> 1.0824322 | K10: =+J10*1.02 -> 1.1040808
B11: 544889 | E11: Population Change Rate | G11: 0.00025 | H11: 0.00025 | I11: 0.00025 | J11: 0.00025 | K11: 0.00025 | M11: RTP pop projections
D14: TABLE 5: North Shore Operating Costs
D16: Plan Element | F16: FY 25-26 | G16: FY 26-27 | H16: FY 27-28 | I16: FY 28-29 | J16: FY 29-30 | K16: FY 30-31
D18: Placer TART Base Case Operating Cost 1
E19: Marginal Operating Costs | G19: =($B$3*G2)+($B$6*G3) -> 3518708.7 | H19: =($B$3*H2)+($B$6*H3) -> 3659457 | I19: =($B$3*I2)+($B$6*I3) -> 3805835.3 | J19: =($B$3*J2)+($B$6*J3) -> 4034930.6 | K19: =($B$3*K2)+($B$6*K3) -> 4182236.5
E20: Fixed Costs | G20: ='VRH Rates'!F14 -> 3188061.3 | H20: =G20*$O$1 -> 3315583.8 | I20: =H20*$O$1 -> 3448207.1 | J20: =I20*$O$1 -> 3586135.4 | K20: =J20*$O$1 -> 3729580.8
E21: Total | F21: =SUM(F19:F20) -> 0 | G21: =SUM(G19:G20) -> 6706770 | H21: =SUM(H19:H20) -> 6975040.8 | I21: =SUM(I19:I20) -> 7254042.4 | J21: =SUM(J19:J20) -> 7621066.1 | K21: =SUM(K19:K20) -> 7911817.3
D23: Placer TART Connect Base Case Operating Cost
E24: Marginal Operating Costs | G24: =($B$8*G7)+($B$11*G8) -> 1273090.1 | H24: =($B$8*H7)+($B$11*H8) -> 1324013.7 | I24: =($B$8*I7)+($B$11*I8) -> 1376974.2 | J24: =($B$8*J7)+($B$11*J8) -> 1432053.2 | K24: =($B$8*K7)+($B$11*K8) -> 1489335.3
E25: Fixed Costs | G25: ='VRH Rates'!F15 -> 1724488 | H25: =G25*$O$1 -> 1793467.5 | I25: =H25*$O$1 -> 1865206.2 | J25: =I25*$O$1 -> 1939814.5 | K25: =J25*$O$1 -> 2017407
E26: Total | F26: =SUM(F24:F25) -> 0 | G26: =SUM(G24:G25) -> 2997578.1 | H26: =SUM(H24:H25) -> 3117481.2 | I26: =SUM(I24:I25) -> 3242180.5 | J26: =SUM(J24:J25) -> 3371867.7 | K26: =SUM(K24:K25) -> 3506742.4 | Q26: Implementation Plan - Do not Delete
D28: TNT/TMA Program Operating Costs2
E29: North Lake Tahoe Express | G29: ='TNTTMA $'!F22 -> 694260 | H29: =G29*$O$1 -> 722030.4 | I29: =H29*$O$1 -> 750911.62 | J29: =I29*$O$1 -> 780948.08 | K29: =J29*$O$1 -> 812186
E30: Park and Ride Shuttles | F30: ='TNTTMA $'!E43 -> 756470 | G30: ='TNTTMA $'!F43 -> 894233 | H30: =G30*$O$1 -> 930002.32 | I30: =H30*$O$1 -> 967202.41 | J30: =I30*$O$1 -> 1005890.5 | K30: =J30*$O$1 -> 1046126.1
E31: Van Pools | F31: ='TNTTMA $'!J43 -> 220818 | G31: ='TNTTMA $'!K43 -> 195800 | H31: =G31*$O$1 -> 203632 | I31: =H31*$O$1 -> 211777.28 | J31: =I31*$O$1 -> 220248.37 | K31: =J31*$O$1 -> 229058.31
E32: Program Administration | F32: ='TNTTMA $'!J22 -> 276289 | G32: ='TNTTMA $'!K22 -> 321870 | H32: =G32*$O$1 -> 334744.8 | I32: =H32*$O$1 -> 348134.59 | J32: =I32*$O$1 -> 362059.98 | K32: =J32*$O$1 -> 376542.37
E33: Regional Transit Marketing | F33: ='TNTTMA $'!P22 -> 225984 | G33: ='TNTTMA $'!Q22 -> 223823 | H33: =G33*$O$1 -> 232775.92 | I33: =H33*$O$1 -> 242086.96 | J33: =I33*$O$1 -> 251770.44 | K33: =J33*$O$1 -> 261841.25
E34: Total TNT/TMA Program Operating Costs | G34: =SUM(G29:G33) -> 2329986 | H34: =SUM(H29:H33) -> 2423185.4 | I34: =SUM(I29:I33) -> 2520112.9 | J34: =SUM(J29:J33) -> 2620917.4 | K34: =SUM(K29:K33) -> 2725754.1
D35: Service Plan Element Marginal Operating Costs | R35: FY 26-27 | S35: FY 27-28 | T35: FY 28-29 | U35: FY 29-30 | V35: FY 30-31
E36: =Q36 -> Reinstate TART Connect Service in Incline Village | G36: =IF(R36=1,ROUND('[32]T5-F15-18 TART 24-25 Perf'!$L$24*O1^2,-2),0) -> 0 | H36: =IF(S36=1,ROUND('[32]T5-F15-18 TART 24-25 Perf'!$L$24*O1^3,-2),0) -> 1044400 | I36: =IF(T36=1,ROUND('[32]T5-F15-18 TART 24-25 Perf'!$L$24*O1^4,-2),0) -> 1086200 | J36: =IF(U36=1,ROUND('[32]T5-F15-18 TART 24-25 Perf'!$L$24*O1^5,-2),0) -> 1129600 | K36: =IF(V36=1,ROUND('[32]T5-F15-18 TART 24-25 Perf'!$L$24*S1^6,-2),0) -> 1402800 | Q36: Reinstate TART Connect Service in Incline Village | R36: 0 | S36: 1 | T36: 1 | U36: 1 | V36: 1
E37: =Q37 -> Increase Van Pools between Reno and Truckee/North Lake Tahoe | G37: =IF(R37=1,ROUND('TNTTMA $'!$J$46*O1,-2),0) -> 25000 | H37: =IF(S37=1,ROUND('TNTTMA $'!$J$46*O1^2,-2),0) -> 26000 | I37: =IF(T37=1,ROUND('TNTTMA $'!$J$46*O1^3,-2),0) -> 0 | J37: =IF(U37=1,ROUND('TNTTMA $'!$J$46*O1^4,-2),0) -> 0 | K37: =IF(V37=1,ROUND('TNTTMA $'!$J$46*O1^5,-2),0) -> 0 | Q37: Increase Van Pools between Reno and Truckee/North Lake Tahoe | R37: 1 | S37: 1 | T37: 0 | U37: 0 | V37: 0
E39: Total Service Plan Costs | G39: =SUM(G36:G37) -> 25000 | H39: =SUM(H36:H37) -> 1070400 | I39: =SUM(I36:I37) -> 1086200 | J39: =SUM(J36:J37) -> 1129600 | K39: =SUM(K36:K37) -> 1402800
D41: Total North Shore Transit Operating Cost | F41: =F21+F39 -> 0 | G41: =G21+G26+G34+G39 -> 12059334 | H41: =H21+H26+H34+H39 -> 13586107 | I41: =I21+I26+I34+I39 -> 14102536 | J41: =J21+J26+J34+J39 -> 14743451 | K41: =K21+K26+K34+K39 -> 15547114
D43: Note 1: Base Case costs based upon FY 2024-25 actual expenses plus 4% inflation and FY 2025-26 service levels. Assumes 4% annual inflation rate moving forward.
D44: Note 2: Excludes Town of Truckee event shuttles.
D45: Source: LSC Transportation Consultants, Inc.
B51: Questions
D54: TABLE A2: North Shore Financial Plan - Operating | M54: 5-Year Plan Revenues/ Costs
F56: FY 25-26 | G56: FY 26-27 | H56: FY 27-28 | I56: FY 28-29 | J56: FY 29-30 | K56: FY 30-31 | O56: Notes
D58: OPERATING REVENUE - RECCURING APPORTIONED FUNDS | F58: Budget | G58: Budget | T58: 74K for 5311
E59: FTA 5307 (Lake Tahoe UZA) 1 | F59: 2500000 | G59: 2660000 | H59: =ROUND(G59*1.01,-2) -> 2686600 | I59: =ROUND(H59*1.01,-2) -> 2713500 | J59: =ROUND(I59*1.01,-2) -> 2740600 | K59: =ROUND(J59*1.01,-2) -> 2768000 | M59: =SUM(G59:K59) -> 13568700 | O59: 1% increase yearly
E60: FTA 5311 (Caltrans) 1 | F60: 450000 | G60: 290000 | H60: =ROUND(G60*1.01,-2) -> 292900 | I60: =ROUND(H60*1.01,-2) -> 295800 | J60: =ROUND(I60*1.01,-2) -> 298800 | K60: =ROUND(J60*1.01,-2) -> 301800 | M60: =SUM(G60:K60) -> 1479300
...

Sheet t 8-10 Capital Plan
P1: 1.03 | Q1: Inflation
B5: EDIT THIS Table | V5: From TART Transit replacement plan (11/2024) | AA5: 24/25
D6: Table XX: Capital Plan | N6: 5-Year Costs | V6: Gas cutaway | AA6: 151892.04
H8: FY 26-27 | I8: FY 27-28 | J8: FY 28-29 | K8: FY 29-30 | L8: FY 30-31 | P8: Per Unit Costs / Notes (FY 26/27 $) | V8: Gas van (from 24/25 TART budget) | AA8: 81000
D9: Service Plan Capital Costs
E10: Fleet Expansion | H10: =SUM(H11:H16) -> 2343100 | I10: =SUM(I11:I16) -> 0 | J10: =SUM(J11:J16) -> 0 | K10: =SUM(K11:K16) -> 0 | L10: =SUM(L11:L16) -> 0 | N10: =SUM(H10:L10) -> 2343100 | P10: 1168561 | Q10: TTD 26/27 One Gillig Hybrid | V10: Fleet Expansion
E11: Eliminate 19X and Replace with US 50 Service (4 Round Trips) | H11: 0 | I11: 0 | J11: 0 | K11: 0 | L11: 0 | P11: =AA6*'T2-4 A1 TTD LL Costs'!Z129^2 -> 0 | Q11: Est. Gas Cutaway (Based on TART 2024 Purchase) | V11: 0 | W11: Eliminate 19X and Replace with US 50 Service (4 Round Trips)
E12: Seasonal Expansion of Route 28 to Spooner Mobility Hub | H12: =ROUND(V12*P10,-2) -> 2337100 | I12: 0 | J12: 0 | K12: 0 | L12: 0 | P12: =AA8*'T2-4 A1 TTD LL Costs'!Z129^2 -> 0 | Q12: Est. Gas Van (Based on TART 2024 Purchase) | V12: 2 | W12: Seasonal Expansion of Route 28 to Spooner Mobility Hub
E13: Continue to Operate the Emerald Bay Shuttle (Route 30) Beyond the Pilot Period | H13: 0 | I13: =ROUND(V13*P11*P1,-2) -> 0 | J13: 0 | K13: 0 | L13: 0 | V13: 6 | W13: Continue to Operate the Emerald Bay Shuttle (Route 30) Beyond the Pilot Period
E14: Pilot Co-mingled Paratransit/Microtransit Service to Meyers | H14: 6000 | I14: =ROUND(V14*P12,-2) -> 0 | J14: 0 | K14: 0 | L14: 0 | V14: 0 | W14: Pilot Co-mingled Paratransit/Microtransit Service to Meyers
E15: Discontinue Route 50 Deviation to LTCC | H15: 0 | I15: 0 | J15: 0 | K15: 0 | L15: 0 | V15: 0 | W15: Discontinue Route 50 Deviation to LTCC
E16: Reinstate TART Connect Service in Incline Village, NV | H16: 0 | I16: 0 | J16: 0 | K16: 0 | L16: 0 | V16: 0 | W16: Reinstate TART Connect Service in Incline Village, NV
E17: Increase Van Pools between Reno and Truckee/North Lake Tahoe | H17: 0 | I17: 0 | J17: 0 | K17: 0 | L17: 0
E18: Staffing | H18: =SUM(H19:H24) -> 0 | I18: =SUM(I19:I24) -> 64900 | J18: =SUM(J19:J24) -> 28600 | K18: =SUM(K19:K24) -> 0 | L18: =SUM(L19:L24) -> 0 | N18: =SUM(H18:L18) -> 93500 | P18: 9000 | Q18: Est. cost to hire, onboard, train new driver | V18: Staffing
E19: Eliminate 19X and Replace with US 50 Service (4 Round Trips) | H19: 0 | I19: 0 | J19: 0 | K19: 0 | L19: 0 | V19: 0 | W19: Eliminate 19X and Replace with US 50 Service (4 Round Trips)
E20: Seasonal Expansion of Route 28 to Spooner Mobility Hub | H20: 0 | I20: 0 | J20: =ROUND(V20*P18*(P1^2),-2) -> 28600 | K20: 0 | L20: 0 | V20: 3 | W20: Seasonal Expansion of Route 28 to Spooner Mobility Hub
E21: Continue to Operate the Emerald Bay Shuttle (Route 30) Beyond the Pilot Period | H21: 0 | I21: =ROUND(V21*P18*P1,-2) -> 64900 | J21: 0 | K21: 0 | L21: 0 | V21: 7 | W21: Continue to Operate the Emerald Bay Shuttle (Route 30) Beyond the Pilot Period
E22: Pilot Co-mingled Paratransit/Microtransit Service to Meyers | H22: 0 | I22: 0 | J22: 0 | K22: 0 | L22: 0 | V22: 1 | W22: Pilot Co-mingled Paratransit/Microtransit Service to Meyers
E23: Discontinue Route 50 Deviation to LTCC | H23: 0 | I23: 0 | J23: 0 | K23: 0 | L23: 0 | V23: 0 | W23: Discontinue Route 50 Deviation to LTCC
E24: Reinstate TART Connect Service in Incline Village, NV | H24: 0 | I24: 0 | J24: 0 | K24: 0 | L24: 0 | V24: 0 | W24: Reinstate TART Connect Service in Incline Village, NV
E25: Increase Van Pools between Reno and Truckee/North Lake Tahoe | H25: 0 | I25: 0 | J25: 0 | K25: 0 | L25: 0
E26: New Bus Stops | H26: =SUM(H27:H32) -> 0 | I26: =SUM(I27:I32) -> 370800 | J26: =SUM(J27:J32) -> 31800 | K26: =SUM(K27:K32) -> 0 | L26: =SUM(L27:L32) -> 0 | N26: =SUM(H26:L26) -> 402600 | P26: 15000 | Q26: Est. Cost of New Bus Stop with Sign | V26: New Bus Stops
E27: Eliminate 19X and Replace with US 50 Service (4 Round Trips) | H27: 0 | I27: =ROUND(V27*P26*P1,-2) -> 185400 | J27: 0 | K27: 0 | L27: 0 | P27: 100000 | Q27: Est. Total Cost of Bus Shelter in Tahoe | V27: 12 | W27: Eliminate 19X and Replace with US 50 Service (4 Round Trips)
E28: Seasonal Expansion of Route 28 to Spooner Mobility Hub | H28: 0 | I28: 0 | J28: =ROUND(V28*P26*(P1^2),-2) -> 31800 | K28: 0 | L28: 0 | V28: 2 | W28: Seasonal Expansion of Route 28 to Spooner Mobility Hub
E29: Continue to Operate the Emerald Bay Shuttle (Route 30) Beyond the Pilot Period | H29: 0 | I29: =V29*P26*P1 -> 185400 | J29: 0 | K29: 0 | L29: 0 | V29: 12 | W29: Continue to Operate the Emerald Bay Shuttle (Route 30) Beyond the Pilot Period
E30: Pilot Co-mingled Paratransit/Microtransit Service to Meyers | H30: =V30*P27 -> 0 | I30: 0 | J30: 0 | K30: 0 | L30: 0 | V30: 0 | W30: Pilot Co-mingled Paratransit/Microtransit Service to Meyers
E31: Discontinue Route 50 Deviation to LTCC | H31: 0 | I31: 0 | J31: 0 | K31: 0 | L31: 0 | V31: 0 | W31: Discontinue Route 50 Deviation to LTCC
E32: Reinstate TART Connect Service in Incline Village, NV | H32: 0 | I32: 0 | J32: 0 | K32: 0 | L32: 0 | V32: 0 | W32: Reinstate TART Connect Service in Incline Village, NV
E33: Increase Van Pools between Reno and Truckee/North Lake Tahoe | H33: 0 | I33: 0 | J33: 0 | K33: 0 | L33: 0
E34: Bus Pull outs and Pedestrian Crossings | H34: =SUM(H35:H40) -> 0 | I34: =SUM(I35:I40) -> 3696500 | J34: =SUM(J35:J40) -> 0 | K34: =SUM(K35:K40) -> 0 | L34: =SUM(L35:L40) -> 0 | N34: =SUM(H34:L34) -> 3696500 | P34: =ROUNDUP(T35*1.04^8,-3) -> 405000 | Q34: Est. Inclusive Cost of Bus Pull Out | T34: 2019 Lake Transit Bus Pull out est. | V34: Bus Pull outs and Pedestrian Crossings
E35: Eliminate 19X and Replace with US 50 Service (4 Round Trips) | H35: 0 | I35: 0 | J35: 0 | K35: 0 | L35: 0 | P35: 25000 | Q35: Est. Cost of RRFB | T35: 295350 | V35: 0 | W35: Eliminate 19X and Replace with US 50 Service (4 Round Trips)
E36: Seasonal Expansion of Route 28 to Spooner Mobility Hub | H36: 0 | I36: =ROUND(V36*P34,-2) -> 810000 | J36: 0 | K36: 0 | L36: 0 | V36: 2 | W36: Seasonal Expansion of Route 28 to Spooner Mobility Hub
E37: Continue to Operate the Emerald Bay Shuttle (Route 30) Beyond the Pilot Period | H37: 0 | I37: =ROUND((P34*SUM(AE38:AE59))+(P35*SUM(AF38:AF59))*1.03,-2) -> 2886500 | J37: 0 | K37: 0 | L37: 0 | W37: Continue to Operate the Emerald Bay Shuttle (Route 30) Beyond the Pilot Period | AD37: ---->>>>>> | AE37: Pull Out | AF37: RRFB
E38: Pilot Co-mingled Paratransit/Microtransit Service to Meyers | H38: =V38*P35 -> 0 | I38: 0 | J38: 0 | K38: 0 | L38: 0 | V38: 0 | W38: Pilot Co-mingled Paratransit/Microtransit Service to Meyers
E39: Discontinue Route 50 Deviation to LTCC | H39: 0 | I39: 0 | J39: 0 | K39: 0 | L39: 0 | V39: 0 | W39: Discontinue Route 50 Deviation to LTCC
E40: Reinstate TART Connect Service in Incline Village, NV | H40: 0 | I40: 0 | J40: 0 | K40: 0 | L40: 0 | V40: 0 | W40: Reinstate TART Connect Service in Incline Village, NV | AE40: 2 | AF40: 1 | AG40: Bayview
E41: Increase Van Pools between Reno and Truckee/North Lake Tahoe | H41: 0 | I41: 0 | J41: 0 | K41: 0 | L41: 0
E42: TTD Shop Street Facility Priority Improvements | H42: =SUM(H43:H45) -> 27470 | I42: =SUM(I43:I45) -> 42454 | J42: =SUM(J43:J45) -> 6494 | K42: =SUM(K43:K45) -> 45377 | L42: =SUM(L43:L45) -> 95064 | N42: =SUM(H42:L42) -> 216859 | P42: Costs directly sourced from 2023 Facility Condition Assessment Reports.
E43: Transit Repair Shop | H43: 19614 | I43: 9969 | J43: 1985 | K43: 0 | L43: 65349
E44: Tire Shop / Admin Building | H44: 1358 | I44: 23235 | J44: 1985 | K44: 13183 | L44: 20845
...

Sheet INPUTS>>>

Sheet VRH Rates
B3: Operating Cost Rates | C3: FY 26-27
B5: South Shore
C6: Form | D6: Per VSH | E6: Per VSM | F6: Fixed | I6: Tot. Op Cost/VSH | K6: NOTES
B7: TTD Fixed Route Bus | C7: =D27 -> TTDTTD | D7: 123.17 | E7: 1.6 | F7: 2077415.2 | I7: 214.66 | K7: Based on 24/25 actuals plus 4% inflation/yr
B8: TTD Paratransit | C8: =D27 -> TTDTTD | D8: =D7 -> 123.17 | E8: =E7 -> 1.6 | I8: =I7 -> 214.66 | K8: Based on 24/25 actuals plus 4% inflation/yr
B9: Lake Link | C9: =D29 -> SSTMAVia | D9: 65.23 | F9: 43215 | G9: 27195 | H9: =90000+1650+840 -> 92490 | I9: 68.7 | K9: SSTMA Lake Link contract costs for 2027. Plus Fixed Admin costs
B10: Route 30 | C10: =D28 -> TTDVia | I10: 147.8
B12: North Shore
B14: TART Fixed Route | C14: =D30 -> TARTTART | D14: 66.45 | E14: 1.7 | F14: 3188061.3 | I14: 185.83 | K14: Based on 24-25 actuals cost model from Existing Conditions report (+4% inflation/yr) | W14: 24-25 | X14: 26-27*
B15: TART Connect | C15: =D32 -> TARTDowntowner | D15: 46.56 | F15: 1724488 | I15: 107.23 | K15: Based on 24-25 actuals cost model from Existing Conditions report (+5% inflation/yr to reflect contract-specified escation rates) | W15: ='[32]TART cost model 24-25'!$B$44 -> 4003350 | X15: =W15*(1.05)^2 -> 4413693.4
B16: Placer TART Paratransit | C16: =D31 -> TARTTruckee | D16: 127.77784 | F16: 9338.3477 | I16: 134.52933 | K16: Based on 24-25 actuals cost model from Existing Conditions report (+4% inflation/yr)
A18: My Ride to Work | B18: Bus(TART) | I18: =284.34*(1+0.03)^2 -> 301.65631 | K18: Based on contract cost from TART/MRTW FY 24-25 (+3% inflation/yr)
B19: Van(TART) | I19: =96.85*(1+0.03)^2 -> 102.74816 | K19: Based on contract cost from TART/MRTW FY 24-25 (+3% inflation/yr)
B20: Shuttle (P&R) | C20: =D33 -> TNTTMAMRTW | I20: =195.13*(1.03) -> 200.9839 | K20: Based on Park and Ride contract cost from TNTTMA/MRTW FY 25-26 (+3% inflation/yr)
B21: Van(P&R) | I21: =128.75*1.03 -> 132.6125 | K21: Based on Park and Ride contract cost from TNTTMA/MRTW FY 25-26 (+3% inflation/yr)
B25: Agency/Operator Combinations
B27: TTD | C27: TTD | D27: =CONCATENATE(B27,C27) -> TTDTTD
B28: TTD | C28: Via | D28: =CONCATENATE(B28,C28) -> TTDVia
B29: SSTMA | C29: Via | D29: =CONCATENATE(B29,C29) -> SSTMAVia
B30: TART | C30: TART | D30: =CONCATENATE(B30,C30) -> TARTTART
B31: TART | C31: Truckee | D31: =CONCATENATE(B31,C31) -> TARTTruckee
B32: TART | C32: Downtowner | D32: =CONCATENATE(B32,C32) -> TARTDowntowner
B33: TNTTMA | C33: MRTW | D33: =CONCATENATE(B33,C33) -> TNTTMAMRTW

Sheet Fare Rates
B3: One-Way Pax Trip Fare
C5: TTD | D5: TART
B6: Local | C6: 0 | D6: 0
B7: Rural | C7: 0 | D7: 0
B8: Regional fx | C8: 0 | D8: 0
B9: Recreational | C9: 0 | D9: 0
B10: Route 30 | C10: 5

Sheet Operating Stats
D3: FY 2025-26
B6: Service/Route | C6: Agency | D6: Operator | E6: Passenger-Trips | F6: Vehicle Service Hours | G6: Vehicle Service Miles | H6: Data Year
B7: 19X | C7: TTD | D7: TTD | E7: 10747 | F7: 2250.4 | G7: 61381 | H7: 24-25
B8: 22 | C8: TTD | D8: TTD | E8: 18457 | F8: 4409.6 | G8: 121654 | H8: 24-25
B9: 28 | C9: TTD | D9: TTD | E9: 24699 | F9: 1192.7 | G9: 22330 | H9: 24-25
B10: 30 | C10: TTD | D10: Via | E10: 10700 | F10: 3500 | G10: 9850 | H10: 26-27 | I10: estimate
B11: 50 | C11: TTD | D11: TTD | E11: 170332 | F11: 9418.6 | G11: 134562 | H11: 24-25
B12: 51 | C12: TTD | D12: TTD | E12: 115 | F12: 167 | G12: 1700 | H12: 24-25
B13: 55 | C13: TTD | D13: TTD | E13: 55609 | F13: 9312.2 | G13: 111689 | H13: 24-25
B14: ADA Para | C14: TTD | D14: TTD | E14: 14556 | F14: 5429 | G14: 71677 | H14: 24-25
B15: Lake Link | C15: SSTMA | D15: Via | E15: 223047 | F15: 47002 | G15: 366322 | H15: 25-26 | I15: VSH are from contract not actual
B16: LL Z1 | C16: SSTMA | D16: Via | F16: =F15/3 -> 15667.333 | G16: =G15/3 -> 122107.33 | I16: Example
B17: LL Z2 | C17: SSTMA | D17: Via | F17: =F15/3 -> 15667.333 | G17: =G15/3 -> 122107.33 | I17: Example
B18: LL Z3 | C18: SSTMA | D18: Via | F18: =F15/3 -> 15667.333 | G18: =G15/3 -> 122107.33 | I18: Example
B19: West Shore | C19: TART | D19: TART | E19: 21205 | F19: 4237.5 | G19: 82391.1 | H19: 25-26
B20: N Shore | C20: TART | D20: TART | E20: 92011 | F20: 4983.5 | G20: 113132.1 | H20: 25-26
B21: Nevada | C21: TART | D21: TART | E21: 34977 | F21: 4219.3125 | G21: 63697 | H21: 25-26
B22: Main Line | C22: TART | D22: TART | E22: =SUM(E19:E21) -> 148193 | F22: =SUM(F19:F21) -> 13440.312 | G22: =SUM(G19:G21) -> 259220.2
B23: 89 | C23: TART | D23: TART | E23: 71136 | F23: 8331.75 | G23: 167948.7 | H23: 25-26
B24: 267 | C24: TART | D24: TART | E24: 73556 | F24: 8420.2333 | G24: 176999.3 | H24: 25-26
B25: Night | C25: TART | D25: TART | E25: 4725 | F25: 2985 | G25: 57781.2 | H25: 25-26
B26: ADA Para | C26: TART | D26: Truckee | E26: 3573 | F26: 1951.65 | G26: 34749 | H26: 25-26
B27: All | C27: TART | D27: Downtowner | E27: 157369 | F27: 27342.51 | G27: 544888.71 | H27: 25-26 | J27: =E27/F27 -> 5.7554701
B28: TC Z1 | C28: TART | D28: Downtowner | F28: =F27/3 -> 9114.17 | G28: =G27/3 -> 181629.57 | I28: Example
B29: TC Z2 | C29: TART | D29: Downtowner | F29: =F27/3 -> 9114.17 | G29: =G27/3 -> 181629.57 | I29: Example
B30: TC Z3 | C30: TART | D30: Downtowner | F30: =F27/6 -> 4557.085 | G30: =G27/6 -> 90814.785 | I30: Example
B31: TC Z4 | C31: TART | D31: Downtowner | F31: =F27/6 -> 4557.085 | G31: =G27/6 -> 90814.785 | I31: Example
B32: Park&Ride (Winter) | C32: TNTTMA | D32: MRTW | F32: 2500 | I32: Estimate
B33: Park&Ride (Summ) | C33: TNTTMA | D33: MRTW | F33: 500 | I33: Estimate
B34: NLTE | C34: TNTTMA | D34: MRTW | F34: 1200 | I34: Estimate based on budget costs for 25-26
D40: Summary Table (Linked)
D41: TTD Rural | E41: =SUM(E7:E8) -> 29204 | F41: =SUM(F7:F8) -> 6660 | G41: =SUM(G7:G8) -> 183035
D42: TTD Urban | E42: =SUM(E9,E11,E12,E13,E14) -> 265311 | F42: =SUM(F9,F11,F12,F13,F14) -> 25519.5 | G42: =SUM(G9,G11,G12,G13,G14) -> 341958
D43: TTD TOTAL | E43: =SUM(E7:E14) -> 305215 | F43: =SUM(F7:F14) -> 35679.5 | G43: =SUM(G7:G14) -> 534843
D44: LAKE LINK | E44: =E15 -> 223047 | F44: =F15 -> 47002 | G44: =G15 -> 366322
D45: TART TOTAL | E45: =SUM(E19:E26) -> 449376 | F45: =SUM(F19:F26) -> 48569.258 | G45: =SUM(G19:G26) -> 955918.6
D46: TART CONNECT | E46: =E27 -> 157369 | F46: =F27 -> 27342.51 | G46: =G27 -> 544888.71

Sheet FTA Allocation Split (26-27)
C3: FTA and TDA Funding Split Worksheet
D9: FEDERAL FUNDING APPORTIONMENT
D11: FTA Sub-Allocation (5307, 5339, 5310)
N13: INPUTS
N14: 1. NTD information
N15: 2. FTA Apportionment table
E16: TTD | F16: Revenue Miles (urban) | I16: Ridership (22/23)
F17: CA | G17: 483367 | I17: TTD | L17: 489907
F18: NV | G18: 319717 | I18: Placer-TART | L18: 613042 | V18: TOT 26 FTA
E19: Placer-TART | F19: CA | G19: 1207385 | L19: =SUM(L17:L18) -> 1102949 | V19: 4730069
F20: NV | G20: 200731
E21: Population (US Census) | I21: FY27 FTA Apportionments | K21: 5307 | L21: 5339 | M21: 5310 | O21: EXAMPLE. Based on FY 25-26, Increased by 1%
E22: TTD | F22: 31420 | G22: 2020 Census | L22: - | M22: -
E23: Placer-TART | F23: 16643 | G23: 2020 Census | I23: UZA Total | K23: ='25_26 FTA Funding Split (INFO)'!K24*1.01 -> 4296912.7 | L23: ='25_26 FTA Funding Split (INFO)'!L24*1.01 -> 405232.2 | M23: ='25_26 FTA Funding Split (INFO)'!M24*1.01 -> 75224.8
E26: Earned Share Factors
F27: Revenue Miles Factor | H27: Population Factor | J27: Ridership Factor | L27: Final
E28: TTD | F28: =G17+G18 -> 803084 | G28: =F28/F30 -> 0.36318922 | H28: =F22 -> 31420 | I28: =H28/H30 -> 0.65372532 | J28: =L17 -> 489907 | K28: =L17/(L17+L18) -> 0.4441792 | L28: =(G28+I28+K28)/3 -> 0.48703124
E29: Placer | F29: =G19+G20 -> 1408116 | G29: =F29/F30 -> 0.63681078 | H29: =F23 -> 16643 | I29: =H29/H30 -> 0.34627468 | J29: =L18 -> 613042 | K29: =L18/(L17+L18) -> 0.5558208 | L29: =(G29+I29+K29)/3 -> 0.51296876
E30: Total | F30: =SUM(F28:F29) -> 2211200 | H30: =SUM(H28:H29) -> 48063 | J30: =SUM(J28:J29) -> 1102949
E32: Allocation Totals by Operator
F33: 5307-Total | G33: 5307-Ops (75%) | H33: 5307-Cap (25%) | I33: 5339 | J33: 5310
E34: TTD | F34: =K23*L28 -> 2092730.7 | G34: =F34*0.75 -> 1569548.1 | H34: =F34-G34 -> 523182.68 | I34: =L23*L28 -> 197360.74
E35: Placer | F35: =K23*L29 -> 2204182 | G35: =F35*0.75 -> 1653136.5 | H35: =F35-G35 -> 551045.49 | I35: =L23*L29 -> 207871.46 | J35: =M23 -> 75224.8
E36: Total | F36: =SUM(F34:F35) -> 4296912.7 | G36: =SUM(G34:G35) -> 3222684.5 | H36: =SUM(H34:H35) -> 1074228.2 | I36: =SUM(I34:I35) -> 405232.2 | J36: =SUM(J34:J35) -> 75224.8

Sheet Actual Revenues
E1: 19X | F1: 22 | G1: 28 | H1: 50 | I1: 55 | J1: 51 | K1: ADA Para (TTD) | L1: 30 | M1: Lake Link (Zone 1) | N1: Lake Link (Zone 2) | O1: Lake Link (Zone 3) | P1: Mainline | Q1: Hwy 89 | R1: Hwy 267 | S1: Night | T1: ADA Para (Placer) | U1: TART Connect (Zone 1) | V1: TART Connect (Zone 2) | W1: TART Connect (Zone 3) | X1: TART Connect (Zone 4) | Y1: Park&Ride Shuttle (Winter) | Z1: Park&Ride Shuttle (Summer) | AA1: North Lake Tahoe Express | AB1: Vanpools | AC1: Total | AD1: Notes
C3: FTA 5307 (Tahoe UZA) - Formula | E3: 0 | F3: 0 | G3: 83115 | H3: 1012092.1 | I3: 397912.05 | J3: 12088.069 | K3: 459972.75 | AC3: =SUM(E3:L3) -> 1965180 | AD3: Can be used to cover 50% of operating costs (urban rtes), 80% ADA.
C4: FTA 5307 (Tahoe UZA) - CMAQ Funds | E4: 0 | F4: 0 | G4: 0 | H4: 184061 | I4: 147901 | J4: 0 | K4: 168038
C5: FTA 5307 (Tahoe UZA) - Carryover
C6: FTA 5311 NV (NDOT) | AC6: =SUM(E6:J6) -> 0 | AD6: Can be used to cover 50% of operating costs (rural rtes)
C7: FTA 5311 CA (PCTPA)
C8: FTA 5310 | AC8: =SUM(E8:J8) -> 0 | AD8: ADA
C9: FTA 5310 - Carryover
C10: TDA LTF (TRPA) | E10: 209888.04 | F10: 408846.98 | G10: 685.5266 | H10: 640648.39 | I10: 306176.9 | J10: 21031.352 | K10: 221384.49 | AC10: =SUM(E10:J10) -> 1587277.2 | AD10: TTD: 33% to rural, 66% to urban
C11: TDA LTF (PCTPA)
C12: TDA STA (TRPA) | AC12: =SUM(E12:J12) -> 0 | AD12: --
C13: TDA STA (PCTPA)
C14: State of Good Repair
C15: Low Carbon Transit Operations Program (LCTOP) - Operating | AC15: =SUM(E15:J15) -> 0
C16: Electrification Credits | E16: 577.96743 | F16: 1139.3179 | G16: 155.75774 | H16: 1553.6922 | I16: 861.86536 | J16: 109.02459 | K16: 664.67477 | AC16: =SUM(E16:J16) -> 4397.6252
C17: SB 125 (Operating) | E17: 0 | F17: 0 | G17: 0 | H17: 262920.28 | I17: 212457.41 | J17: 24622.31 | K17: 0 | AC17: =SUM(E17:L17) -> 500000
C18: Nevada State Parks | G18: 85000 | AC18: =SUM(E18:L18) -> 85000
C19: Tahoe Douglas Visitor Authority | J19: 100000 | AC19: =SUM(E19:L19) -> 100000
C20: Interest Revenue | AC20: =SUM(E20:J20) -> 0
C21: Keep Tahoe Blue (Emerald Bay Shuttle) | L21: 8322 | AC21: =SUM(E21:J21) -> 0 | AE21: Emerald Bay has already changed
C22: Carbon Reduction Program (Emerald Bay Shuttle) | L22: 271910 | AC22: =SUM(E22:J22) -> 0
C23: El Dorado County (Emerald Bay Shuttle) | L23: 331240 | AC23: =SUM(E23:J23) -> 0
C24: Placer County (Emerald Bay Shuttle) | L24: 8324 | AC24: =SUM(E24:J24) -> 0
C25: Washoe RTC | AA25: 12500
C26: Travel North Tahoe Nevada | AA26: 26417
C27: Reno Tahoe Airport Authority | AA27: 12500
C28: Placer County (Transient Occupancy Tax) | U28: =2900000*(2/6) -> 966666.67 | V28: =2900000*(2/6) -> 966666.67 | W28: =2900000*(1/6) -> 483333.33 | X28: =2900000*(1/6) -> 483333.33 | Y28: 418212 | AA28: 162594
C29: Town of Truckee | AA29: 15500
C30: Visit Truckee Tahoe | AA30: 2932
C31: North Shore Resort Partners
C32: North Shore Local Partners (Free Fares)
C33: Martis Zones of Benefit
C34: Douglas County
C35: City of South Lake Tahoe
C36: Tahoe Blue Events Center Mitigation Fee
C37: South Lake Tahoe Tourism Improvement District (SLTTID) | AC37: =SUM(E37:K37) -> 0 | AD37: Can be used to cover 50% of operating costs (urban rtes), 80% ADA.
C38: Heavenly | AC38: =SUM(E38:J38) -> 0 | AD38: Can be used to cover 50% of operating costs (rural rtes)
C39: Ceasars Entertainment | AC39: =SUM(E39:J39) -> 0 | AD39: ADA
C40: Roundhill Pines Resort | AC40: =SUM(E40:J40) -> 0 | AD40: TTD: 33% to rural, 66% to urban
C41: Advance Learning | AC41: =SUM(E41:J41) -> 0 | AD41: --
...

Sheet Revenue %s
B1: Revenue Conditions | C1: Match Requirements | D1: Revenue Sources | F1: 19X | G1: 22 | H1: 28 | I1: 50 | J1: 55 | K1: 51 | L1: ADA Para (TTD) | M1: 30 | N1: Lake Link (Zone 1) | O1: Lake Link (Zone 2) | P1: Lake Link (Zone 3) | Q1: Mainline | R1: Hwy 89 | S1: Hwy 267 | T1: Night | U1: ADA Para (Placer) | V1: TART Connect (Zone 1) | W1: TART Connect (Zone 2) | X1: TART Connect (Zone 3) | Y1: TART Connect (Zone 4) | Z1: Park&Ride Shuttle (Winter) | AA1: Park&Ride Shuttle (Summer) | AB1: North Lake Tahoe Express | AC1: Vanpools | AD1: Total | AE1: Notes
C3: 50% non-federal | D3: FTA 5307 (Tahoe UZA) - Formula | F3: 0 | G3: 0 | H3: 0.042293836 | I3: 0.51501243 | J3: 0.20248122 | K3: 0.0061511257 | L3: 0.23406139 | M3: 0 | N3: 0 | O3: 0 | P3: 0 | Q3: ='Operating Stats'!F22/'Operating Stats'!F45 -> 0.27672468 | R3: ='Operating Stats'!F23/'Operating Stats'!F45 -> 0.17154369 | S3: ='Operating Stats'!F24/'Operating Stats'!F45 -> 0.17336549 | T3: ='Operating Stats'!F25/'Operating Stats'!F45 -> 0.061458628 | U3: ='Operating Stats'!F26/'Operating Stats'!F45 -> 0.040182825 | V3: 0 | W3: 0 | X3: 0 | Y3: 0 | Z3: 0 | AA3: 0 | AB3: 0 | AC3: 0 | AD3: =SUM(F3:M3) -> 1 | AE3: Can be used to cover 50% of operating costs (urban rtes), 80% ADA.
C4: 50% non-federal | D4: FTA 5307 (Tahoe UZA) - CMAQ Funds | F4: 0 | G4: 0 | H4: 0 | I4: 0.368122 | J4: 0.295802 | K4: 0 | L4: 0.336076 | M4: 0 | N4: 0 | O4: 0 | P4: 0
C5: 50% non-federal | D5: FTA 5307 (Tahoe UZA) - Carryover | F5: 0 | G5: 0 | H5: 0 | I5: 0.368122 | J5: 0.295802 | K5: 0 | L5: 0.336076 | M5: 0 | N5: 0 | O5: 0 | P5: 0
B6: Can only be applied to rural routes (19x and 22) | C6: 50% non-federal | D6: FTA 5311 NV (NDOT) | F6: 0.33921198 | G6: 0.66078802 | H6: 0 | I6: 0 | J6: 0 | K6: 0 | L6: 0 | M6: 0 | N6: 0 | O6: 0 | P6: 0 | AD6: =SUM(F6:K6) -> 1 | AE6: Can be used to cover 50% of operating costs (rural rtes)
B7: Can only be applied to rural routes | C7: 50% non-federal | D7: FTA 5311 CA (PCTPA) | F7: 0 | G7: 0 | H7: 0 | I7: 0 | J7: 0 | K7: 0 | L7: 0 | M7: 0 | N7: 0 | O7: 0 | P7: 0
B8: Can only be applied to ADA routes | C8: 50% non-federal | D8: FTA 5310 | F8: 0 | G8: 0 | H8: 0 | I8: 0 | J8: 0 | K8: 0 | L8: 1 | M8: 0 | N8: 0 | O8: 0 | P8: 0 | AD8: =SUM(F8:K8) -> 0 | AE8: ADA
B9: Can only be applied to ADA routes | C9: 50% non-federal | D9: FTA 5310 - Carryover | F9: 0 | G9: 0 | H9: 0 | I9: 0 | J9: 0 | K9: 0 | L9: 1 | M9: 0 | N9: 0 | O9: 0 | P9: 0
B10: California funding ideally used in CA, but can be used as federal match | C10: no match requirement | D10: TDA LTF (TRPA) | F10: 0.11604605 | G10: 0.22604945 | H10: 0.00037902423 | I10: 0.35421129 | J10: 0.16928368 | K10: 0.01162813 | L10: 0.12240238 | M10: 0 | N10: 0 | O10: 0 | P10: 0 | AD10: =SUM(F10:K10) -> 0.87759762 | AE10: TTD: 33% to rural, 66% to urban
B11: California funding ideally used in CA, but can be used as federal match | C11: no match requirement | D11: TDA LTF (PCTPA) | F11: 0 | G11: 0 | H11: 0 | I11: 0 | J11: 0 | K11: 0 | L11: 0 | M11: 0 | N11: 0 | O11: 0 | P11: 0
B12: California funding ideally used in CA, but can be used as federal match | C12: no match requirement | D12: TDA STA (TRPA) | F12: 0.11604605 | G12: 0.22604945 | H12: 0.00037902423 | I12: 0.35421129 | J12: 0.16928368 | K12: 0.01162813 | L12: 0.12240238 | M12: 0 | N12: 0 | O12: 0 | P12: 0 | AD12: =SUM(F12:K12) -> 0.87759762 | AE12: --
B13: California funding ideally used in CA, but can be used as federal match | C13: no match requirement | D13: TDA STA (PCTPA) | F13: 0 | G13: 0 | H13: 0 | I13: 0 | J13: 0 | K13: 0 | L13: 0 | M13: 0 | N13: 0 | O13: 0 | P13: 0
B14: California funding ideally used in CA, but can be used as federal match | C14: no match requirement | D14: State of Good Repair | F14: 0 | G14: 0 | H14: 0 | I14: 0 | J14: 0 | K14: 0 | L14: 0 | M14: 0 | N14: 0 | O14: 0 | P14: 0
B15: California funding ideally used in CA, but can be used as federal match | C15: no match requirement | D15: Low Carbon Transit Operations Program (LCTOP) - Operating | F15: ='Operating Stats'!F7/'Operating Stats'!F43 -> 0.063072633 | G15: ='Operating Stats'!F8/'Operating Stats'!F43 -> 0.12358918 | H15: ='Operating Stats'!F9/'Operating Stats'!F43 -> 0.033428159 | I15: ='Operating Stats'!F11/'Operating Stats'!F43 -> 0.26397791 | J15: ='Operating Stats'!F13/'Operating Stats'!F43 -> 0.26099581 | K15: ='Operating Stats'!F12/'Operating Stats'!F43 -> 0.0046805589 | L15: ='Operating Stats'!F14/'Operating Stats'!F43 -> 0.1521602 | M15: 0 | N15: 0 | O15: 0 | P15: 0 | AD15: =SUM(F15:K15) -> 0.74974425
B16: not real money | C16: not real money only used as match for other sources | D16: Electrification Credits | F16: 0.11417092 | G16: 0.22505934 | H16: 0.030768177 | I16: 0.30691429 | J16: 0.17025174 | K16: 0.021536573 | L16: 0.13129897 | M16: 0 | N16: 0 | O16: 0 | P16: 0 | AD16: =SUM(F16:K16) -> 0.86870103
B17: California funding ideally used in CA, but can be used as federal match | C17: no match requirement | D17: SB 125 (Operating) | F17: 0 | G17: 0 | H17: 0 | I17: 0.52584056 | J17: 0.42491482 | K17: 0.04924462 | L17: 0 | M17: 0 | N17: 0 | O17: 0 | P17: 0 | AD17: =SUM(F17:M17) -> 1
B18: Only applied to Route 28 | C18: no match requirement | D18: Nevada State Parks | F18: 0 | G18: 0 | H18: 1 | I18: 0 | J18: 0 | K18: 0 | L18: 0 | M18: 0 | N18: 0 | O18: 0 | P18: 0 | AD18: =SUM(F18:M18) -> 1
