Workbook
Name _NST01: #N/A
Name FINAL: #N/A
Name TABLE1: #N/A

Sheet For Slides
A1: HILL COUNTRY TRANSIT DISTRICT
A2: FY2024 Proposed Budget (1/1/24 - 12/31/24)
A3: Presented to Board of Directors 11/20/23
C6: In Service | D6: In Service
B7: Commuter Bus Allocation Based on Census 2020 Population by City | S7: Commuter Bus Allocation Based on Census 2020 Population by City
C8: Vehicles | D8: Vehicles | F8: Cost Estimate | G8: Population | J8: Hours | T8: Cost Estimate | U8: Population | W8: Allocated Cost | X8: Hours
B9: TEMPLE | C9: 9 | D9: 12 | G9: 82073 | H9: =G9/G14 -> 0.24921128 | I9: =H9*$F$14 -> 209935.58 | J9: =F155 -> 39832 | K9: =J9/J14 -> 0.33765089 | L9: =J9/(J9+J10) -> 0.80293501 | S9: TEMPLE | U9: 82073 | V9: =U9/U14 -> 0.24921128 | W9: =V9*$F$14 -> 209935.58 | X9: =$F$30*V9 -> 2332.6176
B10: BELTON | C10: 2 | D10: 3 | G10: 23054 | H10: =G10/G14 -> 0.07000252 | I10: =H10*$F$14 -> 58970.123 | J10: =F134 -> 9776 | K10: =J10/J14 -> 0.082869931 | L10: =J10/(J9+J10) -> 0.19706499 | S10: BELTON | U10: 23054 | V10: =U10/U14 -> 0.07000252 | W10: =V10*$F$14 -> 58970.123 | X10: =$F$30*V10 -> 655.22359
B11: KILLEEN | C11: 11 | D11: 15 | G11: 153143 | H11: =G11/G14 -> 0.4650124 | I11: =H11*$F$14 -> 391726.45 | J11: =F112 -> 49192 | K11: =J11/J14 -> 0.41699444 | L11: =J11/(J11+J12+J13) -> 0.71960211 | S11: KILLEEN | U11: 153143 | V11: =U11/U14 -> 0.4650124 | W11: =V11*$F$14 -> 391726.45 | X11: =$F$30*V11 -> 4352.5161
B12: COPPERAS COVE | C12: 2 | D12: 3 | G12: 37964 | H12: =G12/G14 -> 0.11527612 | I12: =H12*$F$14 -> 97108.604 | J12: =F70 -> 9600 | K12: =J12/J14 -> 0.081378001 | L12: =J12/(J11+J12+J13) -> 0.140433 | S12: COPPERAS COVE | U12: 37964 | V12: =U12/U14 -> 0.11527612 | W12: =V12*$F$14 -> 97108.604 | X12: =$F$30*V12 -> 1078.9845
B13: HARKER HEIGHTS | C13: 2 | D13: 3 | G13: 33097 | H13: =G13/G14 -> 0.10049768 | I13: =H13*$F$14 -> 84659.242 | J13: =F91 -> 9568 | K13: =J13/J14 -> 0.081106741 | L13: =J13/(J11+J12+J13) -> 0.13996489 | S13: HARKER HEIGHTS | U13: 33097 | V13: =U13/U14 -> 0.10049768 | W13: =V13*$F$14 -> 84659.242 | X13: =$F$30*V13 -> 940.65824
C14: =SUM(C9:C13) -> 26 | D14: =SUM(D9:D13) -> 36 | F14: =12*260*3*90 -> 842400 | G14: =SUM(G9:G13) -> 329331 | H14: =SUM(H9:H13) -> 1 | I14: =SUM(I9:I13) -> 842400 | J14: =SUM(J9:J13) -> 117968 | K14: =SUM(K9:K13) -> 1 | T14: =12*260*3*90 -> 842400 | U14: =SUM(U9:U13) -> 329331 | V14: =SUM(V9:V13) -> 1 | W14: =SUM(W9:W13) -> 842400 | X14: =SUM(X9:X13) -> 9360
B16: Average Fare | C16: 1
B18: FY24 Budget Targets
B19: As of 6/6/2023
B20: Fully Allocated Expenses | C20: Avg. Daily | D20: Avg. Fleet During | F20: Annual Vehicle Revenue Hours | I20: Annual Passengers | L20: Proposed | P20: FY23
B21: Microtransit On-demand All Urban Zones | C21: Service Hours | D21: Service Hours | G21: Contingency | H21: Contingency | L21: FY24 | P21: Budget
B22: All Zones - Avg. Wait Times 30min Peak | C22: 260 Weekdays | F22: Budget | G22: +10% | H22: +20% | I22: Low | J22: Med | K22: High | L22: Budget | M22: +10% | N22: +20% | O22: Diff Lo/Hi
B23: 7am - 11am + 3pm - 7pm | C23: 8 | D23: =D14 -> 36 | F23: =(C23*D23*260) -> 74880 | G23: =F23*1.1 -> 82368 | H23: =F23*1.2 -> 89856 | I23: =F23*5 -> 374400 | J23: =F23*5.5 -> 411840 | K23: =F23*6 -> 449280 | L23: =F23*65 -> 4867200 | M23: =G23*65 -> 5353920 | N23: =H23*65 -> 5840640 | R23: =L63+L84+L105+L127+L148 -> 4867200
B24: All Zones - Avg. Wait Times 40min Off Peak | C24: 260 Weekdays
B25: 11am - 3pm + 7pm - 9pm | C25: 6 | D25: =C14 -> 26 | F25: =(C25*D25*260) -> 40560 | G25: =F25*1.1 -> 44616 | H25: =F25*1.2 -> 48672 | I25: =F25*3 -> 121680 | J25: =F25*4 -> 162240 | K25: =F25*5 -> 202800 | L25: =F25*65 -> 2636400 | M25: =G25*65 -> 2900040 | N25: =H25*65 -> 3163680 | R25: =L65+L86+L107+L129+L150 -> 2636400
B26: All Zones - Avg. Wait Times 30min Off Peak | C26: 52 Weekend Days
B27: TNC Service Provider | L27: =L67+L88+L109+L131+L151 -> 670453 | R27: =L67+L88+L109+L131+L151 -> 670453
B28: Medicaid Trips (50 daily) | C28: 8 | D28: 6 | F28: =F68+F89+F110+F132+F153 -> 2528 | G28: =F28*1.1 -> 2780.8 | H28: =F28*1.2 -> 3033.6 | I28: =F28*1.5 -> 3792 | J28: =G28*1.5 -> 4171.2 | K28: =H28*1.5 -> 4550.4 | L28: =F28*65 -> 164320 | M28: =G28*65 -> 180752 | N28: =H28*65 -> 197184 | R28: =L68+L89+L110+L132+L153 -> 164320
B29: Total Microtransit On-demand | F29: =SUM(F23:F28) -> 117968 | G29: =SUM(G23:G28) -> 129764.8 | H29: =SUM(H23:H28) -> 141561.6 | I29: =SUM(I23:I28) -> 499872 | J29: =SUM(J23:J28) -> 578251.2 | K29: =SUM(K23:K28) -> 656630.4 | L29: =SUM(L23:L28) -> 8338373 | M29: =SUM(M23:M28) -> 8434712 | N29: =SUM(N23:N28) -> 9201504
B30: Commuter Bus - Stops in Temple, Belton, Nolanville, Harker Heights, Killeen, Copperas Cove | C30: 12 | D30: 3 | F30: =(C30*D30*260) -> 9360 | G30: =F30*1.1 -> 10296 | H30: =F30*1.2 -> 11232 | I30: =10*5*2*290 -> 29000 | J30: =10*7*2*290 -> 40600 | K30: =10*8*2*290 -> 46400 | L30: =F30*90 -> 842400 | M30: =12*259*86*6 -> 1603728 | N30: =12*259*86*6 -> 1603728
B31: Rural | D31: 20 | F31: 32958.05 | J31: 70000 | L31: 2641604 | M31: 2592992 | N31: 2592992
B32: Fort Cavazos (No Fare) | F32: 56548 | J32: 169644 | L32: =4241400-(F32*10) -> 3675920 | S32: County | T32: State & Fed Funding Allocation | U32: NEMT Revenue | V32: Local Funding Contributions | W32: FY24 Budget Target | X32: FY24 County Funding Commitment
B33: Total Projected Expense | F33: =F29+F30+F31+F32 -> 216834.05 | G33: =G29+G30+G31+G32 -> 140060.8 | H33: =H29+H30+H31+H32 -> 152793.6 | I33: =I29+I30+I31+I32 -> 528872 | J33: =J29+J30+J31+J32 -> 858495.2 | K33: =K29+K30+K31+K32 -> 703030.4 | L33: =L29+L30+L31+L32 -> 15498297 | M33: =SUM(M29:M31) -> 12631432 | N33: =SUM(N29:N31) -> 13398224 | O33: =N33-L33 -> -2100073 | P33: =5149835+2883500+3001770 -> 11035105
B34: Projected Revenue
B35: Federal Grant Revenue | L35: =(L48+L51+L54)*-1 -> -6164398 | M35: =-(2970479+1673250+1253517) -> -5897246 | N35: =-(2970479+1673250+1253517) -> -5897246 | P35: =-(2970479+1673250+1253517) -> -5897246 | S35: Bell County | T35: 60476.325 | U35: 9383 | V35: 134383 | W35: 100793 | X35: 125000 | Z35: =ROUND(W35,0) -> 100793
B36: Federal Grant Carbon Reduction Grant | L36: -500000 | S36: Coryell County | T36: 197197.34 | U36: 30595 | V36: 104111 | W36: 301309 | X36: 50000 | Z36: =ROUND(W36,0) -> 301309
B37: State Revenue | L37: =(L49+L52+L55)*-1 -> -1525568 | M37: =-(415133+519759+601585) -> -1536477 | N37: =-(415133+519759+601585) -> -1536477 | P37: =-(415133+519759+601585) -> -1536477 | S37: Hamilton County | T37: 174565.1 | U37: 0 | V37: 0 | W37: 174565 | X37: 0 | Z37: =ROUND(W37,0) -> 174565
B38: Urban Medicaid Revenue | L38: -1113000 | M38: -1400000 | N38: -1400000 | P38: =-917223-634691-404368 -> -1956282 | S38: Lampasas County | T38: 179759.38 | U38: 27890 | V38: 119839 | W38: 299598 | X38: 68433 | Z38: =ROUND(W38,0) -> 299598
B39: Fare Revenue | L39: =((J29+J30+J31)*C16)*-1 -> -688851.2 | S39: Llano County | T39: 303680.2 | U39: 47116 | V39: 202451 | W39: 506131 | X39: 155335 | Z39: =ROUND(W39,0) -> 506131
B40: Killeen Local | L40: =L117*-1 -> -650000 | S40: Mason County | T40: 88117.345 | U40: 13671 | V40: 58744 | W40: 146862 | X40: 45073 | Z40: =ROUND(W40,0) -> 146862
B41: Temple Local | L41: =L162*-1 -> -308936.66 | S41: Milam County | T41: 601053.05 | U41: 93254 | V41: 215287 | W41: 816341 | X41: 75000 | Z41: =ROUND(W41,0) -> 816341
B42: Belton Local | L42: =L141*-1 -> -55372.768 | S42: Mills County | T42: 116500.41 | U42: 0 | V42: 0 | W42: 116500 | X42: 0 | Z42: =ROUND(W42,0) -> 116500
B43: Copperas Cove Local | L43: =L77*-1 -> -94462.808 | S43: San Saba | T43: 133752.85 | U43: 20752 | V43: 45752 | W43: 179505 | X43: 25000 | Z43: =ROUND(W43,0) -> 179505
B44: Harker Heights Local | L44: =L98*-1 -> -64999.85 | T44: =SUM(T35:T43) -> 1855102 | U44: =SUM(U35:U43) -> 242661 | V44: =SUM(V35:V43) -> 880567 | W44: =SUM(W35:W43) -> 2641604 | X44: =SUM(X35:X43) -> 543841 | Z44: =SUM(Z35:Z43) -> 2641604
...

Sheet ASSUMPTIONS
A1: MAJOR ASSUMPTIONS
A2: WORKING DRAFT
A4: 1 | B4: This workbook provides examples and a working draft 5-year financial model as an attempt to tie operating decisions to return on investment
A5: 2 | B5: It is intended to facilitate further discussions and collaberative input regarding sources and uses of funding streams
A6: 3 | B6: All information presented is for illustrative purposes - No recommendation or decisions are to be made from this draft model without further validation
A7: 4 | B7: Certain categorizations have been made to illustrate how funding may be apportioned in the future
A8: 5 | B8: Validation and collaboration is needed to refine all data
A9: 6 | B9: Proposed date for transition of operations = October 1, 2026
A10: 7 | B10: The model uses 2.5% annual escalation for most expenses
A11: 8 | B11: It is important for the user of this the workbook is not complete as key cost share, service type, and revenue share assumptions need to be defined and agreed upon
A12: 9 | B12: The workbook is designed to allow for incremental progress and adjustments as various options are executed to improve the accurace of the workbook
A13: 10 | B13: Three tabs to focus on: Operating Tab, FY27 Financial Forecast, FTA FY27 Financial Forecast Sub Allocation Example

Sheet SRTP - COMP Factors
A1: DRAFT SRTP used as a source of information
S8: Cost per Hr.
S9: Comps | T9: # of Vehicles
S10: =6131022/28294 -> 216.68983 | T10: 12 | U10: TTD
S11: =6532640/66679 -> 97.971475 | T11: 27 | U11: Vail, Co
S12: =5187138/52795 -> 98.250554 | T12: 37 | U12: Mammoth, Ca
S13: =5603319/57175 -> 98.002956 | T13: 28 | U13: Jackson Hole, Wy
S14: =3558126/40400 -> 88.072426 | T14: 32 | U14: Sun Valley, Id
S15: =4672736/41060 -> 113.80263 | T15: 22 | U15: Steamboat Springs, Co
S16: =11491801/72927 -> 157.57951 | T16: 21 | U16: Park City, Ut
S17: =9677785/55759 -> 173.56454 | T17: 31 | U17: Summit County, Co
S18: =11504947/79931 -> 143.93598 | T18: 22 | U18: Eagle County, Co
S19: =11400000/74899 -> 152.20497 | T19: 33 | U19: Whistler
S21: =46190159/246091 -> 187.69544 | T21: 98 | U21: Aspen
S22: =AVERAGE(S11:S21) -> 131.10805 | T22: Average
R23: 0.34 | S23: =S22*R23 -> 44.576736 | T23: COLA to Tahoe
S24: =SUM(S22:S23) -> 175.68478 | T24: Target Hourly Rate
A25: National and regional comps support the use of $175 per VRH for fixed route services as a target | S25: CA+CO | T25: CO Only
A26: Regional comps suggest a targeted cost of $96-$183 per VRH for fixed route services | S26: =(S11+S12+S13+S15+S16+S17+S18+S19)/8 -> 129.41408 | T26: =(S11+S12+S15+S17+S18+S21)/6 -> 135.8701
R27: 0.289 | S27: =S26*R27 -> 37.400668 | T27: =T26*R27 -> 39.26646
S28: =S26+S27 -> 166.81475 | T28: =T26+T27 -> 175.13656

Sheet Regional COMPs

Sheet Fare Assumptions
C3: Fare
B4: Local | C4: 0
B5: Rural | C5: 5
B6: Regional fx | C6: 7
B7: Recreational | C7: 15

Sheet VRH Rates
B3: VRH Rates
B5: Microtransit | D5: 85
B6: Fixed Route Bus | D6: 175
B7: Commuter | D7: =D6 -> 175

Sheet Avg Pass, Mile Per Hr
B2: Projected Passengers Per Revenue Hour
B3: Micro Meyers | C3: 7
B4: Micro Urban | C4: 7
B5: Fixed Route | C5: 20
B6: Recreation | C6: 7
B8: Estimated Miles Per Vehicle Revenue Hour
B9: Microtransit | C9: 12.8
B10: Fx | C10: 14

Sheet Operating 
A1: LAKE LINK ZONES 1-5
A2: SERVICE HOURS OFF-PEAK SEASON [OCT, NOVEMBER] | B2: 6am | C2: 7am | D2: 8am | E2: 9am | F2: 10am | G2: 11am | H2: 12pm | I2: 1pm | J2: 2pm | K2: 3pm | L2: 4pm | M2: 5pm | N2: 6pm | O2: 7pm | P2: 8pm | Q2: 9pm | R2: 10pm | S2: 11pm | AB2: LAKE LINK - 12 MONTH ROLLING STATISTICS
A3: hr | C3: 1 | D3: 2 | E3: 3 | F3: 4 | G3: 5 | H3: 6 | I3: 7 | J3: 8 | K3: 9 | L3: 10 | M3: 11 | N3: 12 | O3: 13 | P3: 14 | Q3: 15 | R3: 17 | S3: 18 | AC3: 45170 | AD3: 45200 | AE3: 45231 | AF3: 45261 | AG3: 45292 | AH3: 45323 | AI3: 45352 | AJ3: 45383 | AK3: 45413 | AL3: 45444 | AM3: 45474 | AN3: 45505 | AO3: Total
A4: TIME | B4: 0.25 | C4: 0.29166667 | D4: 0.33333333 | E4: 0.375 | F4: 0.41666667 | G4: 0.45833333 | H4: 0.5 | I4: 0.54166667 | J4: 0.58333333 | K4: 0.625 | L4: 0.66666667 | M4: 0.70833333 | N4: 0.75 | O4: 0.79166667 | P4: 0.83333333 | Q4: 0.875 | R4: 0.91666667 | S4: 0.95833333 | AB4: Passengers | AC4: 15390 | AD4: 12235 | AE4: 11359 | AF4: 19738 | AG4: 24392 | AH4: 25301 | AI4: 23546 | AJ4: 18830 | AK4: 19932 | AL4: 24029 | AM4: 25365 | AN4: 24121 | AO4: 244238
A5: Vehicles | C5: 9 | D5: 10 | E5: 10 | F5: 10 | G5: 8 | H5: 8 | I5: 8 | J5: 9 | K5: 9 | L5: 10 | M5: 10 | N5: 10 | O5: 10 | P5: 9 | Q5: 9 | R5: 8 | U5: Weeks | V5: VRH | W5: Expenses | X5: VRM | Y5: Passengers | Z5: Fares | AB5: Vehicle Revenue Hours | AC5: 1929 | AD5: 1430 | AE5: 1315 | AF5: 1924 | AG5: 2463 | AH5: 2572 | AI5: 2619 | AJ5: 2062 | AK5: 2047 | AL5: 2507 | AM5: 2655 | AN5: 2585 | AO5: 26108
A6: Nonpeak days Sunday - Thursday | C6: 5 | D6: 5 | E6: 5 | F6: 5 | G6: 5 | H6: 5 | I6: 5 | J6: 5 | K6: 5 | L6: 5 | M6: 5 | N6: 5 | O6: 5 | P6: 5 | U6: 8 | AB6: Total Vehicle Hours | AC6: 2088 | AD6: 1529 | AE6: 1412 | AF6: 2056 | AG6: 2630 | AH6: 2753 | AI6: 2822 | AJ6: 2230 | AK6: 2221 | AL6: 2717 | AM6: 2880 | AN6: 2825 | AO6: 28163
A7: Peak Days Friday-Saturday | C7: 2 | D7: 2 | E7: 2 | F7: 2 | G7: 2 | H7: 2 | I7: 2 | J7: 2 | K7: 2 | L7: 2 | M7: 2 | N7: 2 | O7: 2 | P7: 2 | Q7: 2 | R7: 2 | AB7: Vehicle Revenue Miles | AC7: 23772 | AD7: 18326 | AE7: 17325 | AF7: 23657 | AG7: 29638 | AH7: 31591 | AI7: 35502 | AJ7: 28463 | AK7: 27637 | AL7: 32486 | AM7: 33127 | AN7: 33199 | AO7: 334723
A8: Service Days | C8: =C7+C6 -> 7 | D8: =D7+D6 -> 7 | E8: =E7+E6 -> 7 | F8: =F7+F6 -> 7 | G8: =G7+G6 -> 7 | H8: =H7+H6 -> 7 | I8: =I7+I6 -> 7 | J8: =J7+J6 -> 7 | ... R8: =R7+R6 -> 2 | AB8: Total Vehicle Miles | AC8: 25004 | AD8: 19081 | AE8: 18119 | AF8: 24593 | AG8: 30803 | AH8: 32863 | AI8: 33785 | AJ8: 29681 | AK8: 28887 | AL8: 33981 | AM8: 34744 | AN8: 34825 | AO8: 346366
A9: SERVICE BY HOUR | U9: Weekly Hours | AB9: Passenger Miles | AC9: 24785 | AD9: 19110 | AE9: 17402 | AF9: 29440 | AG9: 38011 | AH9: 41594 | AI9: 38682 | AJ9: 33069 | AK9: 37284 | AL9: 47653 | AM9: 48929 | AN9: 46932 | AO9: 422891
A10: Nonpeak days Sunday - Thursday | C10: =C5*C6 -> 45 | D10: =D5*D6 -> 50 | E10: =E5*E6 -> 50 | F10: =F5*F6 -> 50 | G10: =G5*G6 -> 40 | H10: =H5*H6 -> 40 | I10: =I5*I6 -> 40 | J10: =J5*J6 -> 45 | ... R10: =R5*R6 -> 0 | U10: =SUM(B10:T10) -> 650
A11: Peak Days Friday-Saturday | C11: =C5*C7 -> 18 | D11: =D5*D7 -> 20 | E11: =E5*E7 -> 20 | F11: =F5*F7 -> 20 | G11: =G5*G7 -> 16 | H11: =H5*H7 -> 16 | I11: =I5*I7 -> 16 | J11: =J5*J7 -> 18 | ... R11: =R5*R7 -> 16 | U11: =SUM(B11:T11) -> 294 | AB11: Passengers | AC11: 0.063012308 | AD11: 0.05009458 | AE11: 0.046507914 | AF11: 0.080814615 | AG11: 0.099869799 | AH11: 0.10359158 | AI11: 0.096405965 | AJ11: 0.07709693 | AK11: 0.081608922 | AL11: 0.098383544 | AM11: 0.10385362 | AN11: 0.098760226 | AO11: 1
A12: Total Service Hours - by hour of the day | C12: =SUM(C10:C11) -> 63 | D12: =SUM(D10:D11) -> 70 | E12: =SUM(E10:E11) -> 70 | F12: =SUM(F10:F11) -> 70 | G12: =SUM(G10:G11) -> 56 | H12: =SUM(H10:H11) -> 56 | I12: =SUM(I10:I11) -> 56 | J12: =SUM(J10:J11) -> 63 | ... R12: =SUM(R10:R11) -> 16 | U12: =SUM(U10:U11) -> 944 | V12: =U12*U6 -> 7552 | W12: =V12*'VRH Rates'!D5 -> 641920 | X12: =V12*$AC$24 -> 96947.235 | Y12: =V12*'Avg Pass, Mile Per Hr'!C4 -> 52864 | Z12: =Y12*'Fare Assumptions'!C4 -> 0 | AB12: Vehicle Revenue Hours | AC12: 0.073885399 | AD12: 0.054772484 | AE12: 0.050367703 | AF12: 0.073693887 | AG12: 0.0943389 | AH12: 0.098513865 | AI12: 0.10031408 | AJ12: 0.078979623 | AK12: 0.078405087 | AL12: 0.096024207 | AM12: 0.10169297 | AN12: 0.099011797 | AO12: 1
AB13: Total Vehicle Hours | AC13: 0.074139829 | AD13: 0.054291091 | AE13: 0.050136704 | AF13: 0.073003586 | AG13: 0.093384938 | AH13: 0.09775237 | AI13: 0.10020239 | AJ13: 0.079181905 | AK13: 0.078862337 | AL13: 0.096474097 | AM13: 0.10226183 | AN13: 0.10030892 | AO13: 1
A14: SERVICE HOURS PEAK SEASON [JAN, FEB, MAR, JUN, JUL, AUG] | AB14: Vehicle Revenue Miles | AC14: 0.071019918 | AD14: 0.054749748 | AE14: 0.051759216 | AF14: 0.07067635 | AG14: 0.088544856 | AH14: 0.094379532 | AI14: 0.10606382 | AJ14: 0.085034491 | AK14: 0.082566779 | AL14: 0.097053384 | AM14: 0.098968401 | AN14: 0.099183504 | AO14: 1
A15: Vehicles | C15: 11 | D15: 11 | E15: 11 | F15: 10 | G15: 10 | H15: 10 | I15: 9 | J15: 9 | K15: 9 | L15: 11 | M15: 11 | N15: 11 | O15: 11 | P15: 9 | Q15: 9 | R15: 8 | U15: Weeks | V15: VRH | W15: Expenses | X15: VRM | Y15: Passengers | Z15: Fares | AB15: Total Vehicle Miles | AC15: 0.072189534 | AD15: 0.055089125 | AE15: 0.052311717 | AF15: 0.071002928 | AG15: 0.088931939 | AH15: 0.094879405 | AI15: 0.097541329 | AJ15: 0.085692591 | AK15: 0.083400218 | AL15: 0.098107205 | AM15: 0.10031008 | AN15: 0.10054393 | AO15: 1
A16: Nonpeak days Sunday - Thursday | C16: 5 | D16: 5 | E16: 5 | F16: 5 | G16: 5 | H16: 5 | I16: 5 | J16: 5 | K16: 5 | L16: 5 | M16: 5 | N16: 5 | O16: 5 | P16: 5 | U16: 27 | AB16: Passenger Miles | AC16: 0.058608483 | AD16: 0.045188949 | AE16: 0.041150084 | AF16: 0.069616048 | AG16: 0.089883682 | AH16: 0.098356314 | AI16: 0.091470379 | AJ16: 0.078197455 | AK16: 0.088164562 | AL16: 0.11268388 | AM16: 0.11570121 | AN16: 0.11097895 | AO16: 1
A17: Peak Days Friday-Saturday | C17: 2 | D17: 2 | E17: 2 | F17: 2 | G17: 2 | H17: 2 | I17: 2 | J17: 2 | K17: 2 | L17: 2 | M17: 2 | N17: 2 | O17: 2 | P17: 2 | Q17: 2 | R17: 2
A18: Service Days | C18: =C17+C16 -> 7 | D18: =D17+D16 -> 7 | E18: =E17+E16 -> 7 | F18: =F17+F16 -> 7 | G18: =G17+G16 -> 7 | H18: =H17+H16 -> 7 | I18: =I17+I16 -> 7 | J18: =J17+J16 -> 7 | ... R18: =R17+R16 -> 2
A19: SERVICE BY HOUR | U19: Weekly Hours
A20: Nonpeak days Sunday - Thursday | C20: =C15*C16 -> 55 | D20: =D15*D16 -> 55 | E20: =E15*E16 -> 55 | F20: =F15*F16 -> 50 | G20: =G15*G16 -> 50 | H20: =H15*H16 -> 50 | I20: =I15*I16 -> 45 | J20: =J15*J16 -> 45 | ... R20: =R15*R16 -> 0 | U20: =SUM(B20:T20) -> 715
A21: Peak Days Friday-Saturday | C21: =C15*C17 -> 22 | D21: =D15*D17 -> 22 | E21: =E15*E17 -> 22 | F21: =F15*F17 -> 20 | G21: =G15*G17 -> 20 | H21: =H15*H17 -> 20 | I21: =I15*I17 -> 18 | J21: =J15*J17 -> 18 | ... R21: =R15*R17 -> 16 | U21: =SUM(B21:T21) -> 320
A22: Total Service Hours - by hour of the day | C22: =SUM(C20:C21) -> 77 | D22: =SUM(D20:D21) -> 77 | E22: =SUM(E20:E21) -> 77 | F22: =SUM(F20:F21) -> 70 | G22: =SUM(G20:G21) -> 70 | H22: =SUM(H20:H21) -> 70 | I22: =SUM(I20:I21) -> 63 | J22: =SUM(J20:J21) -> 63 | ... R22: =SUM(R20:R21) -> 16 | U22: =SUM(U20:U21) -> 1035 | V22: =U22*U16 -> 27945 | W22: =V22*'VRH Rates'!D5 -> 2375325 | X22: =V22*'Avg Pass, Mile Per Hr'!C9 -> 357696 | Y22: =V22*'Avg Pass, Mile Per Hr'!C4 -> 195615 | Z22: =Y22*'Fare Assumptions'!C4 -> 0
AB23: Miles per RH | AC23: =AC7/AC5 -> 12.323484 | AD23: =AD7/AD5 -> 12.815385 | AE23: =AE7/AE5 -> 13.174905 | AF23: =AF7/AF5 -> 12.295738 | AG23: =AG7/AG5 -> 12.033293 | AH23: =AH7/AH5 -> 12.282659 | AI23: =AI7/AI5 -> 13.555556 | AJ23: =AJ7/AJ5 -> 13.803589 | ... AO23: =AO7/AO5 -> 12.820706 | AP23: =AVERAGE(AC23:AO23) -> 12.837293
A24: SERVICE HOURS OFF-PEAK SEASON [SEP, DEC, APR, MAY] | AB24: Average Miles Per Rev Hour | AC24: =AVERAGE(AC23:AP23) -> 12.837293
A25: Vehicles | C25: 11 | D25: 10 | E25: 10 | F25: 9 | G25: 9 | H25: 8 | I25: 8 | J25: 8 | K25: 8 | L25: 11 | M25: 11 | N25: 11 | O25: 10 | P25: 9 | Q25: 9 | R25: 8 | U25: Weeks | V25: VRH | W25: Expenses | X25: VRM | Y25: Passengers | Z25: Fares
A26: Nonpeak days Sunday - Thursday | C26: 5 | D26: 5 | E26: 5 | F26: 5 | G26: 5 | H26: 5 | I26: 5 | J26: 5 | K26: 5 | L26: 5 | M26: 5 | N26: 5 | O26: 5 | P26: 5 | U26: 17
A27: Peak Days Friday-Saturday | C27: 2 | D27: 2 | E27: 2 | F27: 2 | G27: 2 | H27: 2 | I27: 2 | J27: 2 | K27: 2 | L27: 2 | M27: 2 | N27: 2 | O27: 2 | P27: 2 | Q27: 2 | R27: 2
A28: Service Days | C28: =C27+C26 -> 7 | D28: =D27+D26 -> 7 | E28: =E27+E26 -> 7 | F28: =F27+F26 -> 7 | G28: =G27+G26 -> 7 | H28: =H27+H26 -> 7 | I28: =I27+I26 -> 7 | J28: =J27+J26 -> 7 | ... R28: =R27+R26 -> 2
A29: SERVICE BY HOUR | U29: Weekly Hours
A30: Nonpeak days Sunday - Thursday | C30: =C25*C26 -> 55 | D30: =D25*D26 -> 50 | E30: =E25*E26 -> 50 | F30: =F25*F26 -> 45 | G30: =G25*G26 -> 45 | H30: =H25*H26 -> 40 | I30: =I25*I26 -> 40 | J30: =J25*J26 -> 40 | ... R30: =R25*R26 -> 0 | U30: =SUM(B30:T30) -> 665
A31: Peak Days Friday-Saturday | C31: =C25*C27 -> 22 | D31: =D25*D27 -> 20 | E31: =E25*E27 -> 20 | F31: =F25*F27 -> 18 | G31: =G25*G27 -> 18 | H31: =H25*H27 -> 16 | I31: =I25*I27 -> 16 | J31: =J25*J27 -> 16 | ... R31: =R25*R27 -> 16 | U31: =SUM(B31:T31) -> 300
A32: Total Service Hours - by hour of the day | C32: =SUM(C30:C31) -> 77 | D32: =SUM(D30:D31) -> 70 | E32: =SUM(E30:E31) -> 70 | F32: =SUM(F30:F31) -> 63 | G32: =SUM(G30:G31) -> 63 | H32: =SUM(H30:H31) -> 56 | I32: =SUM(I30:I31) -> 56 | J32: =SUM(J30:J31) -> 56 | ... R32: =SUM(R30:R31) -> 16 | U32: =SUM(U30:U31) -> 965 | V32: =U32*U26 -> 16405 | W32: =V32*'VRH Rates'!D5 -> 1394425 | X32: =V32*'Avg Pass, Mile Per Hr'!C9 -> 209984 | Y32: =V32*'Avg Pass, Mile Per Hr'!C4 -> 114835 | Z32: =Y32*'Fare Assumptions'!C4 -> 0
U33: Zone 1 -5 TOTAL | V33: =V32+V22+V12 -> 51902 | W33: =W32+W22+W12 -> 4411670 | X33: =X32+X22+X12 -> 664627.23 | Y33: =Y32+Y22+Y12 -> 363314 | Z33: =Z32+Z22+Z12 -> 0
A34: SERVICE OPTIONS
A35: ZONE 6 SERVICE HOURS ROUTE 55 Replacement | B35: 6am | C35: 7am | D35: 8am | E35: 9am | F35: 10am | G35: 11am | H35: 12pm | I35: 1pm | J35: 2pm | K35: 3pm | L35: 4pm | M35: 5pm | N35: 6pm | O35: 7pm | P35: 8pm | Q35: 9pm | R35: 10pm | S35: 11pm | U35: ZONE 6 SERVICE HOURS ROUTE 55 Replacement
C36: 1 | D36: 2 | E36: 3 | F36: 4 | G36: 5 | H36: 6 | I36: 7 | J36: 8 | K36: 9 | L36: 10 | M36: 11 | N36: 12 | O36: 13 | P36: 14 | Q36: 15 | R36: 17 | S36: 18 | U36: Weeks | V36: VRH | W36: Expenses | X36: VRM | Y36: Passengers | Z36: Fares
A37: TIME | B37: 0.25 | C37: 0.29166667 | D37: 0.33333333 | E37: 0.375 | F37: 0.41666667 | G37: 0.45833333 | H37: 0.5 | I37: 0.54166667 | J37: 0.58333333 | K37: 0.625 | L37: 0.66666667 | M37: 0.70833333 | N37: 0.75 | O37: 0.79166667 | P37: 0.83333333 | Q37: 0.875 | R37: 0.91666667 | S37: 0.95833333 | U37: 52
A38: Vehicles | C38: 2 | D38: 2 | E38: 2 | F38: 2 | G38: 2 | H38: 2 | I38: 2 | J38: 2 | K38: 2 | L38: 2 | M38: 2 | N38: 2 | O38: 2 | P38: 2
A39: Weekdays Only | C39: 5 | D39: 5 | E39: 5 | F39: 5 | G39: 5 | H39: 5 | I39: 5 | J39: 5 | K39: 5 | L39: 5 | M39: 5 | N39: 5 | O39: 5 | P39: 5
A41: Total Service Hours - by hour of the day | C41: =C38*C39 -> 10 | D41: =D38*D39 -> 10 | E41: =E38*E39 -> 10 | F41: =F38*F39 -> 10 | G41: =G38*G39 -> 10 | H41: =H38*H39 -> 10 | I41: =I38*I39 -> 10 | J41: =J38*J39 -> 10 | ... P41: =P38*P39 -> 10 | U41: Weekly Hours
...

Sheet Zone 1-5 Peak Vehicles
B3: PEAK VEHICLE DEMAND
E4: Early AM
B5: SERVICE HOURS OFF-PEAK SEASON [OCT, NOVEMBER] | C5: Peak | D5: Off-Peak | E5: Off-Peak
B6: Zone 1 | C6: 2 | D6: 1.5 | E6: 1
B7: Zone 2 | C7: 3 | D7: 3 | E7: 3
B8: Zone 3 | C8: 1 | D8: 1 | E8: 2
B9: Zone 4 | C9: 1 | D9: 1
B10: Zone 5 | C10: 2 | D10: 1.5 | E10: 1
B11: ADA Overflow | C11: 1 | D11: 1 | E11: 1
B12: Total | C12: =SUM(C6:C11) -> 10 | D12: =SUM(D6:D11) -> 9 | E12: =SUM(E6:E11) -> 8
E14: Early AM
B15: SERVICE HOURS PEAK SEASON [JAN, FEB, MAR, JUN, JUL, AUG] | C15: Peak | D15: Off-Peak | E15: Off-Peak
B16: Zone 1 | C16: 2 | D16: 2 | E16: 1
B17: Zone 2 | C17: 4 | D17: 3 | E17: 3
B18: Zone 3 | C18: 1 | D18: 1 | E18: 2
B19: Zone 4 | C19: 1 | D19: 1
B20: Zone 5 | C20: 2 | D20: 2 | E20: 1
B21: ADA Overflow | C21: 1 | D21: 1 | E21: 1
B22: Total | C22: =SUM(C16:C21) -> 11 | D22: =SUM(D16:D21) -> 10 | E22: =SUM(E16:E21) -> 8
B24: SERVICE HOURS OFF-PEAK SEASON [SEP, DEC, APR, MAY] | C24: Peak | D24: Off-Peak | E24: Off-Peak
B25: Zone 1 | C25: 2 | D25: 2 | E25: 1
B26: Zone 2 | C26: 4 | D26: 3 | E26: 3
B27: Zone 3 | C27: 1 | D27: 1 | E27: 2
B28: Zone 4 | C28: 1 | D28: 1
B29: Zone 5 | C29: 2 | D29: 2 | E29: 1
B30: ADA Overflow | C30: 1 | D30: 1 | E30: 1
B31: Total | C31: =SUM(C25:C30) -> 11 | D31: =SUM(D25:D30) -> 10 | E31: =SUM(E25:E30) -> 8

Sheet FY27 Financial Forecast
C1: DRAFT
C2: EXAMPLE 5 YEAR FINANCIAL MODEL - Operating
C3: Revenue & Expense Assumptions (10/1/26 - 09/30/31) | P3: need to address local match for route 19/22, 28 Urban UZA vs Rural
A6: 34 | C6: Revenue Sources | I6: FY2027 | J6: FY2028 | K6: FY2029 | L6: FY2023 | M6: FY2031 | N6: Total
A7: 35 | C7: Caltrans Congestion Mitigation Air Quality (CMAQ) | I7: =500000*0.7 -> 350000 | J7: =500000*0.7 -> 350000 | K7: =500000*0.7 -> 350000 | L7: =500000*0.7 -> 350000 | M7: =500000*0.7 -> 350000 | N7: =SUM(I7:M7) -> 1750000
A8: 37 | C8: Federal Transit Administration Allocations
A9: 41 | C9: FTA 5307 Block Grant | I9: ='FTA FY27 Sub Allocation Exampl '!J32 -> 1322921 | J9: =I9*1.01 -> 1336150.2 | K9: =J9*1.01 -> 1349511.7 | L9: =K9*1.01 -> 1363006.8 | M9: =L9*1.01 -> 1376636.9 | N9: =SUM(I9:M9) -> 6748226.5
A10: 42 | C10: FTA 5311 Allocation (For Portion of Rural El Dorado County) covered by JPA - Funidng Source may need to come from El Dorado County Transit??? | I10: 0 | J10: 0 | K10: 0 | L10: 0 | M10: 0 | N10: =SUM(I10:M10) -> 0
A11: 43 | C11: FTA 5310 Elderly & Disabilities | N11: =SUM(I11:M11) -> 0
A12: 44 | C12: California Transportation Development Act (TDA)
A13: 45 | C13: SGR Growth Projected at 1.5% annually (state of good repair) | N13: =SUM(I13:M13) -> 0
C14: LTF (JPA Full Amount?) (Growth Projected at 1.5% annually) | I14: 1338438 | J14: =I14*1.015 -> 1358514.6 | K14: =J14*1.015 -> 1378892.3 | L14: =K14*1.015 -> 1399575.7 | M14: =L14*1.015 -> 1420569.3 | N14: =SUM(I14:M14) -> 6895989.8
C15: STA (Growth Projected at 1.5% annually) | I15: =1363577*('FTA FY27 Sub Allocation Exampl '!I22) -> 900611.55 | J15: =I15*1.015 -> 914120.72 | K15: =J15*1.015 -> 927832.54 | L15: =K15*1.015 -> 941750.02 | M15: =L15*1.015 -> 955876.27 | N15: =SUM(I15:M15) -> 4640191.1
C16: Surface Transportation Block Grant (STBG) ??? | N16: =SUM(I16:M16) -> 0
C17: City of South Lake Tahoe | I17: 1150000 | J17: 1150000 | K17: 1200000 | L17: 1400000 | M17: 1560000 | N17: =SUM(I17:M17) -> 6460000
C18: El Dorado County | I18: 400000 | J18: 400000 | K18: 400000 | L18: 400000 | M18: 400000 | N18: =SUM(I18:M18) -> 2000000
C19: SSTMA Funding Partners: Event Center, Douglas County, LTVA, TDVA, Others
C20: Event Center | I20: 350000 | J20: 350000 | K20: 350000 | L20: 350000 | M20: 350000 | N20: =SUM(I20:M20) -> 1750000
C21: Douglas County | I21: 600000 | J21: 600000 | K21: 600000 | L21: 600000 | M21: 600000 | N21: =SUM(I21:M21) -> 3000000
C22: LTVA | I22: 50000 | J22: 50000 | K22: 50000 | L22: 50000 | M22: 50000 | N22: =SUM(I22:M22) -> 250000
C23: Other Partners | I23: 100000 | J23: 100000 | K23: 100000 | L23: 100000 | M23: 100000 | N23: =SUM(I23:M23) -> 500000
C24: Parking Revenue
C25: TBID/TOT, Other | J25: 1700000 | K25: 2100000 | L25: 2100000 | M25: 2200000 | N25: =SUM(I25:M25) -> 8100000
C26: CAT 7/10 FHWY | N26: =SUM(I26:M26) -> 0
C27: California SB125 (California) South Shore Transit Operations Support (must be a TDA Operator)* | I27: =1768000 -> 1768000 | J27: =400000-106820 -> 293180 | N27: =SUM(I27:M27) -> 2061180
C28: *$13M allocated $4M for south shore operations $2.1 unallocated
C29: Emerald Bay Fares = $15 per ride, each way | I29: ='Operating '!Z56 -> 514080 | J29: =I29 -> 514080 | K29: =J29 -> 514080 | L29: =K29 -> 514080 | M29: =L29 -> 514080 | N29: =SUM(I29:M29) -> 2570400
C30: Meyers Fare = $5.00 Downtowner+Uber | I30: ='Operating '!Z90 -> 347445 | J30: =I30 -> 347445 | K30: =J30 -> 347445 | L30: =K30 -> 347445 | M30: =L30 -> 347445 | N30: =SUM(I30:M30) -> 1737225
C32: Total Revenue All Sources | I32: =SUM(I7:I31) -> 9191495.5 | J32: =SUM(J7:J31) -> 9463490.5 | K32: =SUM(K7:K31) -> 9667761.5 | L32: =SUM(L7:L31) -> 9915857.5 | M32: =SUM(M7:M31) -> 10224607 | N32: =SUM(I32:M32) -> 48463212
C33: Total Lake Link Operating Expenses by year | I33: ='Operating '!W33 -> 4411670 | J33: =I33*1.025 -> 4521961.8 | K33: =J33*1.025 -> 4635010.8 | L33: =K33*1.025 -> 4750886.1 | M33: =L33*1.025 -> 4869658.2 | N33: =SUM(I33:M33) -> 23189187
C34: Total Fx Bus Operting Expenses by year | I34: ='Operating '!W93 -> 2873500 | J34: =I34*1.025 -> 2945337.5 | K34: =J34*1.025 -> 3018970.9 | L34: =K34*1.025 -> 3094445.2 | M34: =L34*1.025 -> 3171806.3 | N34: =SUM(I34:M34) -> 15104060
C35: Total Projected Operating Expenses (Lake Link + fx bus) | I35: =SUM(I33:I34) -> 7285170 | J35: =SUM(J33:J34) -> 7467299.2 | K35: =SUM(K33:K34) -> 7653981.7 | L35: =SUM(L33:L34) -> 7845331.3 | M35: =SUM(M33:M34) -> 8041464.6 | N35: =SUM(I35:M35) -> 38293247
C36: Zone 6 LTCC to Stateline Service | I36: ='Operating '!W42 -> 618800 | J36: =I36*1.025 -> 634270 | K36: =J36*1.025 -> 650126.75 | L36: =K36*1.025 -> 666379.92 | M36: =L36*1.025 -> 683039.42 | N36: =SUM(I36:M36) -> 3252616.1
C37: Total Projected Operating Expenses (w/Zone 6) | I37: =I35+I36 -> 7903970 | J37: =J35+J36 -> 8101569.2 | K37: =K35+K36 -> 8304108.5 | L37: =L35+L36 -> 8511711.2 | M37: =M35+M36 -> 8724504 | N37: =N35+N36 -> 41545863
C38: South Lake Tahoe Portions of Route 19 | J38: =I38*1.025 -> 0 | K38: =J38*1.025 -> 0 | L38: =K38*1.025 -> 0 | M38: =L38*1.025 -> 0 | N38: =M38*1.025 -> 0
C39: Total Projected Operating Expenses (w/Routee 19) | I39: =I37+I38 -> 7903970 | J39: =J37+J38 -> 8101569.2 | K39: =K37+K38 -> 8304108.5 | L39: =L37+L38 -> 8511711.2 | M39: =M37+M38 -> 8724504 | N39: =N37+N38 -> 41545863
C40: South Lake Tahoe Portions of Route 22 | J40: =I40*1.025 -> 0 | K40: =J40*1.025 -> 0 | L40: =K40*1.025 -> 0 | M40: =L40*1.025 -> 0 | N40: =M40*1.025 -> 0
C41: Total Projected Operating Expenses (w/Route 22) | I41: =I39+I40 -> 7903970 | J41: =J39+J40 -> 8101569.2 | K41: =K39+K40 -> 8304108.5 | L41: =L39+L40 -> 8511711.2 | M41: =M39+M40 -> 8724504 | N41: =N39+N40 -> 41545863
C42: South Lake Tahoe Portions of Route 28 Eeast Shore Express | J42: =I42*1.025 -> 0 | K42: =J42*1.025 -> 0 | L42: =K42*1.025 -> 0 | M42: =L42*1.025 -> 0 | N42: =M42*1.025 -> 0
C43: Total Projected Operating Expenses (w/Route 28) | I43: =I41+I42 -> 7903970 | J43: =J41+J42 -> 8101569.2 | K43: =K41+K42 -> 8304108.5 | L43: =L41+L42 -> 8511711.2 | M43: =M41+M42 -> 8724504 | N43: =N41+N42 -> 41545863
...

Sheet FTA FY27 Sub Allocation Exampl 
B2: FEDERAL FUNDING APPORTIONMENT DISCUSSIONS AND "EXAMPLE" DATA
B4: FTA Sub-Allocation (5307, 5339, 5310)
F5: https://www.transit.dot.gov/funding/apportionments/current-apportionments
K7: 1. Updated with current NTD information
C8: EXAMPLE Using Proposed 2027 Forecasted Regional Model | K8: 2. Updated Allocation amounts from the FTA Apportionment table
C9: TTD | D9: Revenue Miles (urban) | G9: Ridership
D10: fx +micro | E10: ='Operating '!X99 -> 1177425.6 | F10: =E10/D22 -> 0.66695624 | I10: ='Operating '!Y101 -> 925136 | J10: =I10/I12 -> 0.60659246 | K10: Miles + Ridership
D11: 19/22+28+VP | E11: ='Operating '!X100 -> 587946 | F11: =E11/D22 -> 0.33304376 | G11: Placer-TART | I11: 600000 | J11: =I11/I12 -> 0.39340754
C12: Placer-TART | D12: Revenue Miles (urban) | I12: =SUM(I10:I11) -> 1525136
D13: CA | E13: 596889
D14: NV | E14: 85857 | G14: FY24 FTA Allocation 5307 | I14: 5339 | J14: 5310
C15: Population (US Census) | G15: CA | H15: 2682893 | I15: - | K15: =H15/H17 -> 0.68753098
C16: TTD | D16: 31420 | E16: 2020 Census | G16: NV | H16: 1219321 | I16: - | J16: - | K16: =H16/H17 -> 0.31246902
C17: Placer-TART | D17: 16643 | E17: 2020 Census | G17: TOTAL | H17: =SUM(H15:H16) -> 3902214 | I17: 345232 | J17: 64333
C20: Earned Share Factors
D21: Revenue Miles Factor | F21: Population Factor | H21: Ridership Factor | I21: Forecasted % in 2027
C22: TTD | D22: =E10+E11 -> 1765371.6 | E22: =D22/D24 -> 0.72111389 | F22: =D16 -> 31420 | G22: =F22/F24 -> 0.65372532 | H22: =I10/(I10+I11) -> 0.60659246 | I22: =(E22+G22+H22)/3 -> 0.66047722
C23: Placer | D23: =E13+E14 -> 682746 | E23: =D23/D24 -> 0.27888611 | F23: =D17 -> 16643 | G23: =F23/F24 -> 0.34627468 | H23: =I11/(I10+I11) -> 0.39340754 | I23: =(E23+G23+H23)/3 -> 0.33952278
C24: Total | D24: =SUM(D22:D23) -> 2448117.6 | F24: =SUM(F22:F23) -> 48063
C26: 2024 Base + Earned Allocations | H26: "EXAMPLE" Totals by Operator (Earned + Base)
D27: 5307-Base | E27: 5307-Earned | I27: 5307-Total | J27: 5307-Ops (75%) | K27: 5307-Cap (25%) | L27: 5339 | M27: 5310
C28: TTD | D28: 1300000 | E28: =(H17-D30)*I22 -> 1256369 | H28: TTD | I28: =D28+E28 -> 2556369 | J28: =I28*0.75 -> 1917276.8 | K28: =I28*0.25 -> 639092.26 | L28: =I17*I22 -> 228017.87 | M28: 64333
C29: Placer | D29: 700000 | E29: =(H17-D30)*I23 -> 645844.98 | G29: EXAMPLE | H29: Placer | I29: =D29+E29 -> 1345845 | J29: =I29*0.75 -> 1009383.7 | K29: =I29*0.25 -> 336461.24 | L29: =I17*I23 -> 117214.13 | M29: 0
C30: Total | D30: =SUM(D28:D29) -> 2000000 | E30: =SUM(E28:E29) -> 1902214 | G30: *Split | H30: Total | I30: =SUM(I28:I29) -> 3902214 | J30: =SUM(J28:J29) -> 2926660.5 | K30: =SUM(K28:K29) -> 975553.5 | L30: =SUM(L28:L29) -> 345232 | M30: =SUM(M28:M29) -> 64333
E31: =SUM(D30:E30) -> 3902214 | G31: 0.31 | H31: fx 19/22, 28ESxp | I31: =I28*G31 -> 792474.4 | J31: =J28*G31 -> 594355.8 | K31: =K28*G31 -> 198118.6 | L31: =L28*G31 -> 70685.541 | M31: =M28*G31 -> 19943.23
G32: 0.69 | H32: Micro + 50fx | I32: =I28*G32 -> 1763894.6 | J32: =J28*G32 -> 1322921 | K32: =K28*G32 -> 440973.66 | L32: =L28*G32 -> 157332.33 | M32: =M28*G32 -> 44389.77
H33: FY2024 | I33: =SUM(I31:I32) -> 2556369 | J33: =SUM(J31:J32) -> 1917276.8 | K33: =SUM(K31:K32) -> 639092.26 | L33: =SUM(L31:L32) -> 228017.87 | M33: =SUM(M31:M32) -> 64333
G34: *Split should use similar formula focused on area currently served by TTD in California and Nevada

Sheet rt 19,22,28 Cost Share
B2: Determine equitable cost and revenue split for services connnecting multiple regional destination cities based on benefits to each jursidication. What is the ROI?
B3: Determine best service type: Commuter bus, Urban Commuter Bus, Cutaway, Light Duty Van, Vanpool
B4: Determine best operator to deliver the service and develop IGSA bewteen stakeholers directly benefiting from the service
D6: Potential Operator = JAC/Douglas County
D7: Estimated Operating Expense | H7: ='FY27 Financial Forecast'!I69 -> 593775
B8: Route 19 | D8: Carson /JAC | H8: Douglas County | L8: JPA/City of South Lake Tahoe
D9: Miles | E9: Hours | F9: Stops | G9: Ridership | H9: Miles | I9: Hours | J9: Stops | K9: Ridership | L9: Miles | M9: Hours | N9: Stops | O9: Ridership
D10: 0.4 | E10: 0.45 | F10: 0.45 | G10: 0.4 | H10: 0.4 | I10: 0.45 | J10: 0.45 | K10: 0.2 | L10: 0.2 | M10: 0.1 | N10: 0.1 | O10: 0.4
D11: =SUM(D10:G10)/4 -> 0.425 | H11: =SUM(H10:K10)/4 -> 0.375 | L11: =SUM(L10:O10)/4 -> 0.2
D12: =H7*D11 -> 252354.38 | H12: =H7*H11 -> 222665.62 | L12: =H7*L11 -> 118755
C13: Federal 5311 | D13: =D12/2 -> 126177.19 | H13: =H12/2 -> 111332.81
C14: State/Local | D14: =D12/2 -> 126177.19 | H14: =H12/2 -> 111332.81 | L14: =L12 -> 118755
C15: Share | G15: =D12 -> 252354.38 | K15: =H12 -> 222665.62 | O15: =L12 -> 118755
D18: Potential Operator JAC/Douglas County
D19: Estimated Operating Expense | H19: ='FY27 Financial Forecast'!I70 -> 593775
B20: Route 22 | D20: Carson /JAC | H20: Douglas County | L20: JPA/City of South Lake Tahoe
D21: Miles | E21: Hours | F21: Stops | G21: Ridership | H21: Miles | I21: Hours | J21: Stops | K21: Ridership | L21: Miles | M21: Hours | N21: Stops | O21: Ridership
D22: 0.4 | E22: 0.45 | F22: 0.45 | G22: 0.4 | H22: 0.4 | I22: 0.45 | J22: 0.45 | K22: 0.2 | L22: 0.2 | M22: 0.1 | N22: 0.1 | O22: 0.4
D23: =SUM(D22:G22)/4 -> 0.425 | H23: =SUM(H22:K22)/4 -> 0.375 | L23: =SUM(L22:O22)/4 -> 0.2
D24: =H19*D23 -> 252354.38 | H24: =H19*H23 -> 222665.62 | L24: =H19*L23 -> 118755
C25: Federal 5311 | D25: =D24/2 -> 126177.19 | H25: =H24/2 -> 111332.81
C26: State/Local | D26: =D24/2 -> 126177.19 | H26: =H24/2 -> 111332.81 | L26: =L24 -> 118755
C27: Share | G27: =D24 -> 252354.38 | K27: =H24 -> 222665.62 | O27: =L24 -> 118755
D29: Potential Operator TART?
D30: Estimated Operating Expense | H30: ='FY27 Financial Forecast'!I72 -> 446775
B31: Route 28 | D31: TART | H31: Douglas County | L31: JPA/City of South Lake Tahoe
D32: Miles | E32: Hours | F32: Stops | G32: Ridership | H32: Miles | I32: Hours | J32: Stops | K32: Ridership | L32: Miles | M32: Hours | N32: Stops | O32: Ridership
D33: 1 | E33: 1 | F33: 1 | G33: 1
D34: =SUM(D33:G33)/4 -> 1
D35: =H30 -> 446775
C36: Federal 5307 | D36: =D35/2 -> 223387.5
C37: State/Local | D37: =D35/2 -> 223387.5
C38: Share | G38: =D35 -> 446775 | K38: =H35 -> 0 | O38: =L35 -> 0
D41: Potential Operators = JAC/Douglas County/JPA
D42: Estimated Operating Expense | H42: =(30*3000*12)/3 -> 360000
B43: Vanpool Option for Route 19/22 | D43: Carson /JAC | H43: Douglas County | L43: JPA/City of South Lake Tahoe
D44: Miles | E44: Hours | F44: Stops | G44: Ridership | H44: Miles | I44: Hours | J44: Stops | K44: Ridership | L44: Miles | M44: Hours | N44: Stops | O44: Ridership
D45: 0.4 | E45: 0.45 | F45: 0.45 | G45: 0.4 | H45: 0.4 | I45: 0.45 | J45: 0.45 | K45: 0.2 | L45: 0.2 | M45: 0.1 | N45: 0.1 | O45: 0.4
D46: =SUM(D45:G45)/4 -> 0.425 | H46: =SUM(H45:K45)/4 -> 0.375 | L46: =SUM(L45:O45)/4 -> 0.2
D47: =H42*D46 -> 153000 | H47: =H42*H46 -> 135000 | L47: =H42*L46 -> 72000
...

Sheet FTA Sub Allocation 2024 Model
A1: FTA Sub-Allocation (5307, 5339, 5310) | E1: FY24 Full Year Apportionments
E2: https://www.transit.dot.gov/funding/apportionments/current-apportionments
B5: National Transit Database and TRPA LT Info Data (2021/2022)
B6: TTD | C6: Revenue Miles (urban) | F6: Ridership
C7: CA | D7: 266378.81 | F7: TTD | H7: =269576 -> 269576
C8: NV | D8: 157442.19 | F8: Placer-TART | H8: 490752
B9: Placer-TART | C9: Revenue Miles (urban) | H9: =SUM(H7:H8) -> 760328
C10: CA | D10: 625051
C11: NV | D11: 85334 | F11: FY21 FTA Allocation 5307 | H11: 5339 | I11: 5310
B12: Population (US Census) | F12: CA | G12: 2682893 | H12: -
B13: TTD | C13: 31420 | D13: 2020 Census | F13: NV | G13: 1219321 | H13: - | I13: -
B14: Placer-TART | C14: 16643 | D14: 2020 Census | F14: TOTAL | G14: =SUM(G12:G13) -> 3902214 | H14: 356088 | I14: 67399
B17: Earned Share Factors
C18: Revenue Miles Factor | E18: Population Factor | G18: Ridership Factor | H18: Final %
B19: TTD | C19: =D7+D8 -> 423821 | D19: =C19/C21 -> 0.37367198 | E19: =C13 -> 31420 | F19: =E19/E21 -> 0.65372532 | G19: =H7/(H7+H8) -> 0.35455225 | H19: =(D19+F19+G19)/3 -> 0.46064985
B20: Placer | C20: =D10+D11 -> 710385 | D20: =C20/C21 -> 0.62632802 | E20: =C14 -> 16643 | F20: =E20/E21 -> 0.34627468 | G20: =H8/(H7+H8) -> 0.64544775 | H20: =(D20+F20+G20)/3 -> 0.53935015
B21: Total | C21: =SUM(C19:C20) -> 1134206 | E21: =SUM(E19:E20) -> 48063
B23: 5307 Operating Assistance Special Rule - FY24 | G23: Totals by Operator
C24: Max Section 5307 Operating Assistance Allowed 5307(a)(2)(B) | H24: 5307-Total | I24: 5307-Ops (75%) | J24: 5307-Cap (25%) | K24: 5339 | L24: 5310
G25: TTD | H25: 1352065.3 | I25: =H25*0.75 -> 1014049 | J25: =H25*0.25 -> 338016.33 | K25: =H14*H19 -> 164031.88 | L25: 0
B26: TTD | C26: 1014049 | G26: Placer | H26: 2550148.7 | I26: =H26*0.75 -> 1912611.5 | J26: =H26*0.25 -> 637537.17 | K26: =H14*H20 -> 192056.12 | L26: =I14 -> 67399
B27: Placer | C27: 2205277 | G27: Total | H27: =SUM(H25:H26) -> 3902214 | I27: =SUM(I25:I26) -> 2926660.5 | J27: =SUM(J25:J26) -> 975553.5 | K27: =SUM(K25:K26) -> 356088 | L27: =SUM(L25:L26) -> 67399

Sheet FTA FY23 FULL Modified
A1: FTA Sub-Allocation (5307, 5339, 5310) | E1: FY23 Full Year Apportionments
E2: https://www.transit.dot.gov/funding/apportionments/current-apportionments
J4: 1. Updated with current NTD information
B5: National Transit Database and TRPA LT Info Data (2020/2021) | J5: 2. Updated Allocation amounts from the FTA Apportionment table
B6: TTD | C6: Revenue Miles (urban) | F6: Ridership | H6: 20/21
C7: CA | D7: 300196.81 | F7: TTD | H7: 257443
C8: NV | D8: 177430.19 | F8: Placer-TART | H8: 199752
B9: Placer-TART | C9: Revenue Miles (urban) | H9: =SUM(H7:H8) -> 457195
C10: CA | D10: 596889
C11: NV | D11: 85857 | F11: FY21 FTA Allocation 5307 | H11: 5339 | I11: 5310
B12: Population (US Census) | F12: CA | G12: 2647686 | H12: -
B13: TTD | C13: 31420 | D13: 2020 Census | F13: NV | G13: 1197619 | H13: - | I13: -
B14: Placer-TART | C14: 16643 | D14: 2020 Census | F14: TOTAL | G14: =SUM(G12:G13) -> 3845305 | H14: 345232 | I14: 64333
B17: Earned Share Factors
C18: Revenue Miles Factor | E18: Population Factor | G18: Ridership Factor | H18: Final %
B19: TTD | C19: =D7+D8 -> 477627 | D19: =C19/C21 -> 0.41161506 | E19: =C13 -> 31420 | F19: =E19/E21 -> 0.65372532 | G19: =H7/(H7+H8) -> 0.56309233 | H19: =(D19+F19+G19)/3 -> 0.5428109 | I19: 0.5428109
B20: Placer | C20: =D10+D11 -> 682746 | D20: =C20/C21 -> 0.58838494 | E20: =C14 -> 16643 | F20: =E20/E21 -> 0.34627468 | G20: =H8/(H7+H8) -> 0.43690767 | H20: =(D20+F20+G20)/3 -> 0.4571891 | I20: 0.4571891
B21: Total | C21: =SUM(C19:C20) -> 1160373 | E21: =SUM(E19:E20) -> 48063
B23: Base + Earned Allocations | G23: Totals by Operator (Earned + Base)
C24: 5307-Base | D24: 5307-Earned | H24: 5307-Total | I24: 5307-Ops (75%) | J24: 5307-Cap (25%) | K24: 5339 | L24: 5310
B25: TTD | C25: 1300000 | D25: =(G14-C27)*H19 -> 1001651.7 | G25: TTD | H25: =(G14-SUM(C25:C26))*H19+C25 -> 2301651.7 | I25: =H25*0.75 -> 1726238.8 | J25: =H25*0.25 -> 575412.92 | K25: =H14*H19 -> 187395.69 | L25: 64333
B26: Placer | C26: 700000 | D26: =(G14-C27)*H20 -> 843653.32 | G26: Placer | H26: =(G14-SUM(C25:C26))*H20+C26 -> 1543653.3 | I26: =H26*0.75 -> 1157740 | J26: =H26*0.25 -> 385913.33 | K26: =H14*H20 -> 157836.31 | L26: 0
B27: Total | C27: =SUM(C25:C26) -> 2000000 | D27: =SUM(D25:D26) -> 1845305 | G27: Total | H27: =SUM(H25:H26) -> 3845305 | I27: =SUM(I25:I26) -> 2883978.8 | J27: =SUM(J25:J26) -> 961326.25 | K27: =SUM(K25:K26) -> 345232 | L27: =SUM(L25:L26) -> 64333
D28: =SUM(C27:D27) -> 3845305

Sheet FY 2024 5307 & 5340 Table 3 (2)
A1: FEDERAL TRANSIT ADMINISTRATION
A2: Table 3
A4: FY 2024 FULL YEAR SECTION 5307 AND SECTION 5340 URBANIZED AREA APPORTIONMENTS
A6: The amount apportioned in this notice includes funding authorized under the Bipartisan Infrastructure Law, enacted as the Infrastructure Investment and Jobs Act (Pub. L. 117-58), and is based on funding made available under the Consolidated Appropriations Act, 2024 (H.R. 4366 / Public Law 118-42, March 9, 2024).
A7: Note: This table shows the amounts attributable to each State of a Multi-State Urbanized Area over 200,000 in population. These amounts are for illustrative purposes only. Designated recipients shall continue to sub-allocate funds allocated to an urbanized area based on a locally determined process, consistent with Section 5307 statutory requirements. Each State's share of a multi-state urbanized area was calculated on the basis of the percentage of population attributable to the States in the UZA, as determined by the 2020 Census.
A9: URBANIZED AREA/STATE | C9: Grand Total
A11: 1,000,000 or more in Population (Large) | C11: =C94 -> 4993057781
A13: 200,000 - 999,999 in Population (Medium) | C13: =C291 -> 1352064684
A15: 50,000 - 199,999 in Population (Small) | C15: =C699 -> 899882095
A17: Total: | C17: =C11+C13+C15 -> 7245004560
A20: Amounts Apportioned to Urbanized Areas 1,000,000 or more in Population:
A21: Atlanta, GA | B21: Georgia | C21: 98814891
A22: Austin, TX | B22: Texas | C22: 49141608
A23: Baltimore, MD | B23: Maryland | C23: 95731989
A24: Boston, MA-NH | B24: Massachusetts | C24: 209208982
A25: Boston, MA-NH | B25: New Hampshire | C25: 2935880
A26: Boston, MA-NH Total | C26: 212144862
A27: Charlotte, NC-SC | B27: North Carolina | C27: 26934025
A28: Charlotte, NC-SC | B28: South Carolina | C28: 406288
A29: Charlotte, NC-SC Total | C29: 27340313
A30: Chicago, IL-IN | B30: Illinois | C30: 313871830
A31: Chicago, IL-IN | B31: Indiana | C31: 20598059
A32: Chicago, IL-IN Total | C32: 334469889
A33: Cincinnati, OH-KY | B33: Kentucky | C33: 5863450
A34: Cincinnati, OH-KY | B34: Ohio | C34: 21933407
A35: Cincinnati, OH-KY Total | C35: 27796857
A36: Cleveland, OH | B36: Ohio | C36: 38112803
A37: Columbus, OH | B37: Ohio | C37: 25683489
A38: Dallas-Fort Worth-Arlington, TX | B38: Texas | C38: 120234995
A39: Denver-Aurora, CO | B39: Colorado | C39: 80953802
A40: Detroit, MI | B40: Michigan | C40: 55066282
A41: Houston, TX | B41: Texas | C41: 117452082
A42: Indianapolis, IN | B42: Indiana | C42: 24659802
A43: Jacksonville, FL | B43: Florida | C43: 22676560
A44: Kansas City, MO-KS | B44: Kansas | C44: 10558563
A45: Kansas City, MO-KS | B45: Missouri | C45: 13274896
A46: Kansas City, MO-KS Total | C46: 23833459
A47: Las Vegas-Henderson-Paradise, NV | B47: Nevada | C47: 55064602
A48: Los Angeles-Long Beach-Anaheim, CA | B48: California | C48: 387165053
A49: Memphis, TN-MS-AR | B49: Arkansas | C49: 522414
...

Sheet Expense Detail
B5: A | C5: B | D5: Projected Annual Budget
D6: FY27 | F6: FY28 | H6: FY29 | J6: FY30 | M6: FY31 | N6: Total | P6: %
A7: 1 | B7: LOCAL DIVISION EXPENSE
A8: 2
A9: 3 | B9: 5110 | C9: SALARIES | D9: ='FY27 Financial Forecast'!$I$37*P9 -> 4833704.2 | F9: ='FY27 Financial Forecast'!$J$37*$P9 -> 4954546.8 | H9: ='FY27 Financial Forecast'!$K$37*$P9 -> 5078410.5 | J9: ='FY27 Financial Forecast'!$L$37*$P9 -> 5205370.8 | M9: ='FY27 Financial Forecast'!$M$37*$P9 -> 5335505 | N9: =SUM(D9:M9) -> 25407537 | P9: 0.61155397
A10: 4. | C10: General Administration | H10: ='FY27 Financial Forecast'!$J$37*$P10 -> 0
A11: 5. | C11: Vehicle Maintenance | H11: ='FY27 Financial Forecast'!$J$37*$P11 -> 0
A12: 6. | C12: Vehicle Operator Others | H12: ='FY27 Financial Forecast'!$J$37*$P12 -> 0
A13: 7. | C13: Vehicle Operators | H13: ='FY27 Financial Forecast'!$J$37*$P13 -> 0
H14: ='FY27 Financial Forecast'!$J$37*$P14 -> 0
A15: 4 | B15: 5210 | C15: FRINGE | D15: ='FY27 Financial Forecast'!$I$37*P15 -> 1139297.9 | F15: ='FY27 Financial Forecast'!$J$37*$P15 -> 1167780.3 | H15: ='FY27 Financial Forecast'!$K$37*$P15 -> 1196974.8 | J15: ='FY27 Financial Forecast'!$L$37*$P15 -> 1226899.2 | M15: ='FY27 Financial Forecast'!$M$37*$P15 -> 1257571.7 | N15: =SUM(D15:M15) -> 5988524 | P15: 0.14414249
A16: 5 | B16: 6310 | C16: CONSULTANT/CONTRACTUAL | D16: ='FY27 Financial Forecast'!$I$37*P16 -> 5520.3681 | F16: ='FY27 Financial Forecast'!$J$37*$P16 -> 5658.3773 | H16: ='FY27 Financial Forecast'!$K$37*$P16 -> 5799.8367 | J16: ='FY27 Financial Forecast'!$L$37*$P16 -> 5944.8326 | M16: ='FY27 Financial Forecast'!$M$37*$P16 -> 6093.4534 | N16: =SUM(D16:M16) -> 29016.868 | P16: 0.00069842979
A17: 6 | B17: 6320 | C17: AUDIT | D17: ='FY27 Financial Forecast'!$I$37*P17 -> 27618.368 | F17: ='FY27 Financial Forecast'!$J$37*$P17 -> 28308.828 | H17: ='FY27 Financial Forecast'!$K$37*$P17 -> 29016.548 | J17: ='FY27 Financial Forecast'!$L$37*$P17 -> 29741.962 | M17: ='FY27 Financial Forecast'!$M$37*$P17 -> 30485.511 | N17: =SUM(D17:M17) -> 145171.22 | P17: 0.00349424
A18: 7 | B18: 6330 | C18: PROFESSIONAL FEES | D18: ='FY27 Financial Forecast'!$I$37*P18 -> 12950.883 | F18: ='FY27 Financial Forecast'!$J$37*$P18 -> 13274.655 | H18: ='FY27 Financial Forecast'!$K$37*$P18 -> 13606.521 | J18: ='FY27 Financial Forecast'!$L$37*$P18 -> 13946.684 | M18: ='FY27 Financial Forecast'!$M$37*$P18 -> 14295.351 | N18: =SUM(D18:M18) -> 68074.094 | P18: 0.0016385288
A19: 8 | B19: 6431 | C19: CONSUMABLE ADMIN SUPPLIES | D19: ='FY27 Financial Forecast'!$I$37*P19 -> 13419.854 | F19: ='FY27 Financial Forecast'!$J$37*$P19 -> 13755.351 | H19: ='FY27 Financial Forecast'!$K$37*$P19 -> 14099.234 | J19: ='FY27 Financial Forecast'!$L$37*$P19 -> 14451.715 | M19: ='FY27 Financial Forecast'!$M$37*$P19 -> 14813.008 | N19: =SUM(D19:M19) -> 70539.162 | P19: 0.0016978625
A20: 9 | B20: 6432 | C20: TECHNOLOGY | D20: ='FY27 Financial Forecast'!$I$37*P20 -> 143339.57 | F20: ='FY27 Financial Forecast'!$J$37*$P20 -> 146923.06 | H20: ='FY27 Financial Forecast'!$K$37*$P20 -> 150596.13 | J20: ='FY27 Financial Forecast'!$L$37*$P20 -> 154361.04 | M20: ='FY27 Financial Forecast'!$M$37*$P20 -> 158220.06 | N20: =SUM(D20:M20) -> 753439.86 | P20: 0.018135136
A21: 10 | C21: PURCHASED TRANSPORTATION (TNC PROVIDER) | D21: ='FY27 Financial Forecast'!$I$37*P21 -> 0 | F21: ='FY27 Financial Forecast'!$J$37*$P21 -> 0 | H21: ='FY27 Financial Forecast'!$K$37*$P21 -> 0 | J21: ='FY27 Financial Forecast'!$L$37*$P21 -> 0 | M21: ='FY27 Financial Forecast'!$M$37*$P21 -> 0 | N21: =SUM(D21:M21) -> 0 | P21: 0
A22: 11 | B22: 6510 | C22: UTILITIES-ADMIN | D22: ='FY27 Financial Forecast'!$I$37*P22 -> 14605.411 | F22: ='FY27 Financial Forecast'!$J$37*$P22 -> 14970.546 | H22: ='FY27 Financial Forecast'!$K$37*$P22 -> 15344.81 | J22: ='FY27 Financial Forecast'!$L$37*$P22 -> 15728.43 | M22: ='FY27 Financial Forecast'!$M$37*$P22 -> 16121.641 | N22: =SUM(D22:M22) -> 76770.839 | P22: 0.0018478576
A23: 12 | B23: 6530 | C23: TELEPHONE-ADMIN | D23: ='FY27 Financial Forecast'!$I$37*P23 -> 3000.2657 | F23: ='FY27 Financial Forecast'!$J$37*$P23 -> 3075.2724 | H23: ='FY27 Financial Forecast'!$K$37*$P23 -> 3152.1542 | J23: ='FY27 Financial Forecast'!$L$37*$P23 -> 3230.958 | M23: ='FY27 Financial Forecast'!$M$37*$P23 -> 3311.732 | N23: =SUM(D23:M23) -> 15770.382 | P23: 0.00037958972
A24: 13 | B24: 6610 | C24: INSURANCE - LIABILITY | D24: ='FY27 Financial Forecast'!$I$37*P24 -> 7881.2109 | F24: ='FY27 Financial Forecast'!$J$37*$P24 -> 8078.2411 | H24: ='FY27 Financial Forecast'!$K$37*$P24 -> 8280.1972 | J24: ='FY27 Financial Forecast'!$L$37*$P24 -> 8487.2021 | M24: ='FY27 Financial Forecast'!$M$37*$P24 -> 8699.3821 | N24: =SUM(D24:M24) -> 41426.233 | P24: 0.00099712054
A25: 14 | B25: 6810 | C25: OFFICE EQUIPMENT LEASING | D25: ='FY27 Financial Forecast'!$I$37*P25 -> 20337.126 | F25: ='FY27 Financial Forecast'!$J$37*$P25 -> 20845.554 | H25: ='FY27 Financial Forecast'!$K$37*$P25 -> 21366.693 | J25: ='FY27 Financial Forecast'!$L$37*$P25 -> 21900.86 | M25: ='FY27 Financial Forecast'!$M$37*$P25 -> 22448.382 | N25: =SUM(D25:M25) -> 106898.61 | P25: 0.0025730267
A26: 15 | B26: 6815 | C26: OFFICE EQUIPMENT/FIXTURES | D26: ='FY27 Financial Forecast'!$I$37*P26 -> 921.2734 | F26: ='FY27 Financial Forecast'!$J$37*$P26 -> 944.30524 | H26: ='FY27 Financial Forecast'!$K$37*$P26 -> 967.91287 | J26: ='FY27 Financial Forecast'!$L$37*$P26 -> 992.11069 | M26: ='FY27 Financial Forecast'!$M$37*$P26 -> 1016.9135 | N26: =SUM(D26:M26) -> 4842.5157 | P26: 0.00011655831
A27: 16 | B27: 6825 | C27: TRAVEL OUT-OF-AREA | D27: ='FY27 Financial Forecast'!$I$37*P27 -> 2302.8293 | F27: ='FY27 Financial Forecast'!$J$37*$P27 -> 2360.4001 | H27: ='FY27 Financial Forecast'!$K$37*$P27 -> 2419.4101 | J27: ='FY27 Financial Forecast'!$L$37*$P27 -> 2479.8953 | M27: ='FY27 Financial Forecast'!$M$37*$P27 -> 2541.8927 | N27: =SUM(D27:M27) -> 12104.427 | P27: 0.00029135097
A28: 17 | B28: 6830 | C28: MILEAGE | D28: ='FY27 Financial Forecast'!$I$37*P28 -> 4184.0754 | F28: ='FY27 Financial Forecast'!$J$37*$P28 -> 4288.6773 | H28: ='FY27 Financial Forecast'!$K$37*$P28 -> 4395.8942 | J28: ='FY27 Financial Forecast'!$L$37*$P28 -> 4505.7916 | M28: ='FY27 Financial Forecast'!$M$37*$P28 -> 4618.4363 | N28: =SUM(D28:M28) -> 21992.875 | P28: 0.00052936377
A29: 18 | B29: 6835 | C29: PUBLIC NOTICES | D29: ='FY27 Financial Forecast'!$I$37*P29 -> 0 | F29: ='FY27 Financial Forecast'!$J$37*$P29 -> 0 | H29: ='FY27 Financial Forecast'!$K$37*$P29 -> 0 | J29: ='FY27 Financial Forecast'!$L$37*$P29 -> 0 | M29: ='FY27 Financial Forecast'!$M$37*$P29 -> 0 | N29: =SUM(D29:M29) -> 0 | P29: 0
A30: 19 | B30: 6840 | C30: REGISTRATION FEES | D30: ='FY27 Financial Forecast'!$I$37*P30 -> 681.78198 | F30: ='FY27 Financial Forecast'!$J$37*$P30 -> 698.82653 | H30: ='FY27 Financial Forecast'!$K$37*$P30 -> 716.2972 | J30: ='FY27 Financial Forecast'!$L$37*$P30 -> 734.20463 | M30: ='FY27 Financial Forecast'!$M$37*$P30 -> 752.55974 | N30: =SUM(D30:M30) -> 3583.6701 | P30: 8.625817e-05
A31: 20 | B31: 6845 | C31: MEMBERSHIP DUES | D31: ='FY27 Financial Forecast'!$I$37*P31 -> 1652.7576 | F31: ='FY27 Financial Forecast'!$J$37*$P31 -> 1694.0765 | H31: ='FY27 Financial Forecast'!$K$37*$P31 -> 1736.4284 | J31: ='FY27 Financial Forecast'!$L$37*$P31 -> 1779.8392 | M31: ='FY27 Financial Forecast'!$M$37*$P31 -> 1824.3351 | N31: =SUM(D31:M31) -> 8687.4368 | P31: 0.00020910474
A32: 21 | B32: 6850 | C32: MARKETING | D32: ='FY27 Financial Forecast'!$I$37*P32 -> -420.40271 | F32: ='FY27 Financial Forecast'!$J$37*$P32 -> -430.91278 | H32: ='FY27 Financial Forecast'!$K$37*$P32 -> -441.6856 | J32: ='FY27 Financial Forecast'!$L$37*$P32 -> -452.72774 | M32: ='FY27 Financial Forecast'!$M$37*$P32 -> -464.04593 | N32: =SUM(D32:M32) -> -2209.7748 | P32: -5.3188804e-05
A33: 22 | B33: 6855 | C33: MISCELLANEOUS ADMIN | D33: ='FY27 Financial Forecast'!$I$37*P33 -> 53212.476 | F33: ='FY27 Financial Forecast'!$J$37*$P33 -> 54542.788 | H33: ='FY27 Financial Forecast'!$K$37*$P33 -> 55906.358 | J33: ='FY27 Financial Forecast'!$L$37*$P33 -> 57304.016 | M33: ='FY27 Financial Forecast'!$M$37*$P33 -> 58736.617 | N33: =SUM(D33:M33) -> 279702.25 | P33: 0.0067323732
... A52: 41 | B52: 9865 | C52: MISCELLANEOUS OPERATING | D52: ='FY27 Financial Forecast'!$I$37*P52 -> 3741.3598 | F52: ='FY27 Financial Forecast'!$J$37*$P52 -> 3834.8938 | H52: ='FY27 Financial Forecast'!$K$37*$P52 -> 3930.7661 | J52: ='FY27 Financial Forecast'!$L$37*$P52 -> 4029.0353 | M52: ='FY27 Financial Forecast'!$M$37*$P52 -> 4129.7612 | N52: =SUM(D52:M52) -> 19665.816 | P52: 0.00047335197
A53: 42 | D53: ='FY27 Financial Forecast'!$I$37*P53 -> 0 | F53: ='FY27 Financial Forecast'!$J$37*$P53 -> 0 | H53: ='FY27 Financial Forecast'!$K$37*$P53 -> 0 | J53: ='FY27 Financial Forecast'!$L$37*$P53 -> 0 | M53: ='FY27 Financial Forecast'!$M$37*$P53 -> 0 | N53: =SUM(D53:M53) -> 0
A54: 43 | B54: 8850 | C54: VEHICLE REPAIR, MAINT., INSPECT., REGISTR. | D54: ='FY27 Financial Forecast'!$I$37*P54 -> 0 | F54: ='FY27 Financial Forecast'!$J$37*$P54 -> 0 | H54: ='FY27 Financial Forecast'!$K$37*$P54 -> 0 | J54: ='FY27 Financial Forecast'!$L$37*$P54 -> 0 | M54: ='FY27 Financial Forecast'!$M$37*$P54 -> 0 | N54: =SUM(D54:M54) -> 0 | P54: 0
A55: 44 | B55: 8855 | C55: VEHICLE MAINT LABOR | D55: ='FY27 Financial Forecast'!$I$37*P55 -> 0 | F55: ='FY27 Financial Forecast'!$J$37*$P55 -> 0 | H55: ='FY27 Financial Forecast'!$K$37*$P55 -> 0 | J55: ='FY27 Financial Forecast'!$L$37*$P55 -> 0 | M55: ='FY27 Financial Forecast'!$M$37*$P55 -> 0 | N55: =SUM(D55:M55) -> 0 | P55: 0
A56: 45 | B56: 9931 | C56: PREV MNT - OTHER VEH MNT MATERIALS | D56: ='FY27 Financial Forecast'!$I$37*P56 -> 189292.52 | F56: ='FY27 Financial Forecast'!$J$37*$P56 -> 194024.84 | H56: ='FY27 Financial Forecast'!$K$37*$P56 -> 198875.46 | J56: ='FY27 Financial Forecast'!$L$37*$P56 -> 203847.34 | M56: ='FY27 Financial Forecast'!$M$37*$P56 -> 208943.53 | N56: =SUM(D56:M56) -> 994983.69 | P56: 0.023949044
A57: 46 | B57: 9932 | C57: PREV MNT - SHOP EQUIPMENT | D57: ='FY27 Financial Forecast'!$I$37*P57 -> 37847.955 | F57: ='FY27 Financial Forecast'!$J$37*$P57 -> 38794.154 | H57: ='FY27 Financial Forecast'!$K$37*$P57 -> 39764.008 | J57: ='FY27 Financial Forecast'!$L$37*$P57 -> 40758.108 | M57: ='FY27 Financial Forecast'!$M$37*$P57 -> 41777.061 | N57: =SUM(D57:M57) -> 198941.29 | P57: 0.004788474
A58: 47 | B58: 9933 | C58: PREV MNT - SHOP SUPPLIES | D58: ='FY27 Financial Forecast'!$I$37*P58 -> 88809.736 | F58: ='FY27 Financial Forecast'!$J$37*$P58 -> 91029.979 | H58: ='FY27 Financial Forecast'!$K$37*$P58 -> 93305.729 | J58: ='FY27 Financial Forecast'!$L$37*$P58 -> 95638.372 | M58: ='FY27 Financial Forecast'!$M$37*$P58 -> 98029.331 | N58: =SUM(D58:M58) -> 466813.15 | P58: 0.011236092
A59: 48 | B59: 9934 | C59: PREV MNT - VEH MNT INVENTORY | D59: ='FY27 Financial Forecast'!$I$37*P59 -> 136507.37 | F59: ='FY27 Financial Forecast'!$J$37*$P59 -> 139920.05 | H59: ='FY27 Financial Forecast'!$K$37*$P59 -> 143418.05 | J59: ='FY27 Financial Forecast'!$L$37*$P59 -> 147003.51 | M59: ='FY27 Financial Forecast'!$M$37*$P59 -> 150678.59 | N59: =SUM(D59:M59) -> 717527.58 | P59: 0.017270735
A60: 49 | B60: 9935 | C60: PREV MNT - FLEET MNT | D60: ='FY27 Financial Forecast'!$I$37*P60 -> 14626.473 | F60: ='FY27 Financial Forecast'!$J$37*$P60 -> 14992.134 | H60: ='FY27 Financial Forecast'!$K$37*$P60 -> 15366.938 | J60: ='FY27 Financial Forecast'!$L$37*$P60 -> 15751.111 | M60: ='FY27 Financial Forecast'!$M$37*$P60 -> 16144.889 | N60: =SUM(D60:M60) -> 76881.545 | P60: 0.0018505223
A61: 50 | B61: 9936 | C61: PREV MNT - VEH REP,MNT,INSP,RG | D61: ='FY27 Financial Forecast'!$I$37*P61 -> 53465.331 | F61: ='FY27 Financial Forecast'!$J$37*$P61 -> 54801.965 | H61: ='FY27 Financial Forecast'!$K$37*$P61 -> 56172.014 | J61: ='FY27 Financial Forecast'!$L$37*$P61 -> 57576.314 | M61: ='FY27 Financial Forecast'!$M$37*$P61 -> 59015.722 | N61: =SUM(D61:M61) -> 281031.35 | P61: 0.0067643642
A62: 51 | B62: 9945 | C62: FACILITY REPAIR & MAINT | D62: ='FY27 Financial Forecast'!$I$37*P62 -> 105900.94 | F62: ='FY27 Financial Forecast'!$J$37*$P62 -> 108548.47 | H62: ='FY27 Financial Forecast'!$K$37*$P62 -> 111262.18 | J62: ='FY27 Financial Forecast'!$L$37*$P62 -> 114043.73 | M62: ='FY27 Financial Forecast'!$M$37*$P62 -> 116894.82 | N62: =SUM(D62:M62) -> 556650.14 | P62: 0.013398449
...

Sheet Service Parameters
C73: ZONE 6 ALTERNATIVE TO ROUTE 55

Sheet Lake Link 23-24 Data
A1: Microtransit 12month Rolling Ridership - 2023/2024
B2: 45170 | C2: 45200 | D2: 45231 | E2: 45261 | F2: 45292 | G2: 45323 | H2: 45352 | I2: 45383 | J2: 45413 | K2: 45444 | L2: 45474 | M2: 45505 | N2: Total
A3: Passengers | B3: 15390 | C3: 12235 | D3: 11359 | E3: 19738 | F3: 24392 | G3: 25301 | H3: 23546 | I3: 18830 | J3: 19932 | K3: 24029 | L3: 25365 | M3: 24121 | N3: 244238
A4: Vehicle Revenue Hours | B4: 1929 | C4: 1430 | D4: 1315 | E4: 1924 | F4: 2463 | G4: 2572 | H4: 2619 | I4: 2062 | J4: 2047 | K4: 2507 | L4: 2655 | M4: 2585 | N4: 26108
A5: Total Vehicle Hours | B5: 2088 | C5: 1529 | D5: 1412 | E5: 2056 | F5: 2630 | G5: 2753 | H5: 2822 | I5: 2230 | J5: 2221 | K5: 2717 | L5: 2880 | M5: 2825 | N5: 28163
A6: Vehicle Revenue Miles | B6: 23772 | C6: 18326 | D6: 17325 | E6: 23657 | F6: 29638 | G6: 31591 | H6: 35502 | I6: 28463 | J6: 27637 | K6: 32486 | L6: 33127 | M6: 33199 | N6: 334723
A7: Total Vehicle Miles | B7: 25004 | C7: 19081 | D7: 18119 | E7: 24593 | F7: 30803 | G7: 32863 | H7: 33785 | I7: 29681 | J7: 28887 | K7: 33981 | L7: 34744 | M7: 34825 | N7: 346366
A8: Passenger Miles | B8: 24785 | C8: 19110 | D8: 17402 | E8: 29440 | F8: 38011 | G8: 41594 | H8: 38682 | I8: 33069 | J8: 37284 | K8: 47653 | L8: 48929 | M8: 46932 | N8: 422891

Sheet TTD 2022 NTD DATA
R22: FY27 | S22: FY28
R23: Vehicle | S23: Vehicle
R24: Revenue | S24: Revenue
R25: Miles | S25: Miles
R28: =(208928/7)*3 -> 89540.571 | S28: =208928/7*4 -> 119387.43 | T28: VRM JPA
R29: =423821-R28 -> 334280.43 | S29: =423821-S28 -> 304433.57 | T29: VRM TTD
R30: =R29+R28 -> 423821 | S30: =S29+S28 -> 423821
R31: 0.75 | S31: 0.75
R32: =(269576-22739)*0.75 -> 185127.75 | T32: Px
R33: =R28/12 -> 7461.7143 | S33: =S28/12 -> 9948.9524 | T33: VRH JPA

Sheet SSTMA CY24 Budget
B3: CY24 Budget
B4: Hendrickson Transporation Group Management Fees | D4: HTG | E4: Downtowner | F4: Admin | G4: Total Total
B5: 45138 | D5: 10625 | E5: 112937 | F5: 150 | G5: =SUM(D5:E5) -> 123562
B6: 45169 | D6: 10625 | E6: 102937 | F6: 150 | G6: =SUM(D6:E6) -> 113562
B7: 45199 | D7: 10625 | E7: 151111 | F7: 150 | G7: =SUM(D7:E7) -> 161736
B8: 45200 | D8: 10625 | E8: 102537 | F8: 150 | G8: =SUM(D8:E8) -> 113162
B9: 45260 | D9: 10625 | E9: 102537 | F9: 150 | G9: =SUM(D9:E9) -> 113162
B10: 45291 | D10: 10625 | E10: 102537 | F10: 150 | G10: =SUM(D10:E10) -> 113162
B11: Expenses | D11: HTG | E11: Downtowner | F11: Admin | G11: Total
B12: January | D12: =10625+(15000/12) -> 11875 | E12: 150395 | F12: 150 | G12: =SUM(D12:F12) -> 162420
B13: February | D13: =10625+(15000/12) -> 11875 | E13: 166786 | F13: 150 | G13: =SUM(D13:F13) -> 178811
B14: March | D14: =10625+(15000/12) -> 11875 | E14: 166786 | F14: 150 | G14: =SUM(D14:F14) -> 178811
B15: April | D15: =10625+(15000/12) -> 11875 | E15: 166786 | F15: 150 | G15: =SUM(D15:F15) -> 178811
B16: May | D16: =10625+(15000/12) -> 11875 | E16: 166786 | F16: 150 | G16: =SUM(D16:F16) -> 178811
B17: June | D17: =10625+(15000/12) -> 11875 | E17: 166786 | F17: 150 | G17: =SUM(D17:F17) -> 178811
